Workbook

Sheet TenantGuard unit economics
A1: TenantGuard unit economics
A2: TenantGuard — Business Plan · Main Scenario
A4: Variable / dimension | B4: Value
A5: Cost per completed remediation | B5: ='TenantGuard inputs'!B9*'TenantGuard inputs'!B7+'TenantGuard inputs'!B10 -> 0.0425
A6: Monthly compute cost per customer | B6: ='TenantGuard unit economics'!B5*'TenantGuard inputs'!B8 -> 4.25
A7: Unit compute gross margin | B7: =1-'TenantGuard unit economics'!B6/'TenantGuard inputs'!B6 -> 0.99346154
A8: Break-even customers | B8: =CEILING('TenantGuard inputs'!B12/('TenantGuard inputs'!B6-'TenantGuard unit economics'!B6),1) -> 78
A9: Revenue in first 12 months | B9: =SUM('TenantGuard three-case revenue'!B6,'TenantGuard three-case revenue'!E6,'TenantGuard three-case revenue'!H6,'TenantGuard three-case revenue'!K6,'TenantGuard three-case revenue'!N6,'TenantGuard three-case revenue'!Q6,'TenantGuard three-case revenue'!T6,'TenantGuard three-case revenue'!W6,'TenantGuard three-case revenue'!Z6,'TenantGuard three-case revenue'!AC6,'TenantGuard three-case revenue'!AF6,'TenantGuard three-case revenue'!AI6) -> 507000
A10: Cash at month 12 | B10: =IF('TenantGuard three-case revenue'!AI8="","",'TenantGuard three-case revenue'!AI8) -> 803685
A11: Runway months under plateau | B11: =IF(IF(IF(ISERROR('Model inputs'!O29<0),'Model inputs'!O29<0,IF('Model inputs'!O29="","",'Model inputs'!O29<0))="",FALSE,IF(ISERROR('Model inputs'!O29<0),'Model inputs'!O29<0,IF('Model inputs'!O29="","",'Model inputs'!O29<0))),12+'TenantGuard unit economics'!B10/(-'Model inputs'!O29),"")
A12: No-revenue runway months | B12: ='TenantGuard inputs'!B13/'TenantGuard inputs'!B12 -> 18

Sheet TenantGuard three-case revenue
A1: TenantGuard three-case revenue ramp
A2: TenantGuard — Business Plan · Main Scenario
A4: Variable / dimension | B4: 2026-10 | C4: 2026-10 > TenantGuard — Low | D4: 2026-10 > TenantGuard — High | E4: 2026-11 | F4: 2026-11 > TenantGuard — Low | G4: 2026-11 > TenantGuard — High | H4: 2026-12 | I4: 2026-12 > TenantGuard — Low | J4: 2026-12 > TenantGuard — High | K4: 2027-01 | L4: 2027-01 > TenantGuard — Low | M4: 2027-01 > TenantGuard — High | N4: 2027-02 | O4: 2027-02 > TenantGuard — Low | P4: 2027-02 > TenantGuard — High | Q4: 2027-03 | R4: 2027-03 > TenantGuard — Low | S4: 2027-03 > TenantGuard — High | T4: 2027-04 | U4: 2027-04 > TenantGuard — Low | V4: 2027-04 > TenantGuard — High | W4: 2027-05 | X4: 2027-05 > TenantGuard — Low | Y4: 2027-05 > TenantGuard — High | Z4: 2027-06 | AA4: 2027-06 > TenantGuard — Low | AB4: 2027-06 > TenantGuard — High | AC4: 2027-07 | AD4: 2027-07 > TenantGuard — Low | AE4: 2027-07 > TenantGuard — High | AF4: 2027-08 | AG4: 2027-08 > TenantGuard — Low | AH4: 2027-08 > TenantGuard — High | AI4: 2027-09 | AJ4: 2027-09 > TenantGuard — Low | AK4: 2027-09 > TenantGuard — High
A5: Ending customers | B5: ='Model inputs'!D23+'Model inputs'!D16-'Model inputs'!D13 -> 10 | C5: ='Model inputs'!D25+'Model inputs'!D18-'Model inputs'!D15 -> 3.3333333 | D5: ='Model inputs'!D24+'Model inputs'!D17-'Model inputs'!D14 -> 21.666667 | E5: ='Model inputs'!E23+'Model inputs'!E16-'Model inputs'!E13 -> 20 | F5: ='Model inputs'!E25+'Model inputs'!E18-'Model inputs'!E15 -> 6.6666667 | G5: ='Model inputs'!E24+'Model inputs'!E17-'Model inputs'!E14 -> 43.333333 | H5: ='Model inputs'!F23+'Model inputs'!F16-'Model inputs'!F13 -> 30 | I5: ='Model inputs'!F25+'Model inputs'!F18-'Model inputs'!F15 -> 10 | J5: ='Model inputs'!F24+'Model inputs'!F17-'Model inputs'!F14 -> 65 | K5: ='Model inputs'!G23+'Model inputs'!G16-'Model inputs'!G13 -> 40 | L5: ='Model inputs'!G25+'Model inputs'!G18-'Model inputs'!G15 -> 13.333333 | M5: ='Model inputs'!G24+'Model inputs'!G17-'Model inputs'!G14 -> 86.666667 | N5: ='Model inputs'!H23+'Model inputs'!H16-'Model inputs'!H13 -> 50 | O5: ='Model inputs'!H25+'Model inputs'!H18-'Model inputs'!H15 -> 16.666667 | P5: ='Model inputs'!H24+'Model inputs'!H17-'Model inputs'!H14 -> 108.33333 | Q5: ='Model inputs'!I23+'Model inputs'!I16-'Model inputs'!I13 -> 60 | R5: ='Model inputs'!I25+'Model inputs'!I18-'Model inputs'!I15 -> 20 | S5: ='Model inputs'!I24+'Model inputs'!I17-'Model inputs'!I14 -> 130 | T5: ='Model inputs'!J23+'Model inputs'!J16-'Model inputs'!J13 -> 70 | U5: ='Model inputs'!J25+'Model inputs'!J18-'Model inputs'!J15 -> 23.333333 | V5: ='Model inputs'!J24+'Model inputs'!J17-'Model inputs'!J14 -> 151.66667 | W5: ='Model inputs'!K23+'Model inputs'!K16-'Model inputs'!K13 -> 80 | X5: ='Model inputs'!K25+'Model inputs'!K18-'Model inputs'!K15 -> 26.666667 | Y5: ='Model inputs'!K24+'Model inputs'!K17-'Model inputs'!K14 -> 173.33333 | Z5: ='Model inputs'!L23+'Model inputs'!L16-'Model inputs'!L13 -> 90 | AA5: ='Model inputs'!L25+'Model inputs'!L18-'Model inputs'!L15 -> 30 | AB5: ='Model inputs'!L24+'Model inputs'!L17-'Model inputs'!L14 -> 195 | AC5: ='Model inputs'!M23+'Model inputs'!M16-'Model inputs'!M13 -> 100 | AD5: ='Model inputs'!M25+'Model inputs'!M18-'Model inputs'!M15 -> 33.333333 | AE5: ='Model inputs'!M24+'Model inputs'!M17-'Model inputs'!M14 -> 216.66667 | AF5: ='Model inputs'!N23+'Model inputs'!N16-'Model inputs'!N13 -> 110 | AG5: ='Model inputs'!N25+'Model inputs'!N18-'Model inputs'!N15 -> 36.666667 | AH5: ='Model inputs'!N24+'Model inputs'!N17-'Model inputs'!N14 -> 238.33333 | AI5: ='Model inputs'!O23+'Model inputs'!O16-'Model inputs'!O13 -> 120 | AJ5: ='Model inputs'!O25+'Model inputs'!O18-'Model inputs'!O15 -> 40 | AK5: ='Model inputs'!O24+'Model inputs'!O17-'Model inputs'!O14 -> 260
A6: TenantGuard revenue | B6: ='TenantGuard three-case revenue'!B5*'TenantGuard inputs'!B6 -> 6500 | C6: ='TenantGuard three-case revenue'!C5*'Model inputs'!C9 -> 1500 | D6: ='TenantGuard three-case revenue'!D5*'Model inputs'!C8 -> 18416.667 | E6: ='TenantGuard three-case revenue'!E5*'TenantGuard inputs'!B6 -> 13000 | F6: ='TenantGuard three-case revenue'!F5*'Model inputs'!C9 -> 3000 | G6: ='TenantGuard three-case revenue'!G5*'Model inputs'!C8 -> 36833.333 | H6: ='TenantGuard three-case revenue'!H5*'TenantGuard inputs'!B6 -> 19500 | I6: ='TenantGuard three-case revenue'!I5*'Model inputs'!C9 -> 4500 | J6: ='TenantGuard three-case revenue'!J5*'Model inputs'!C8 -> 55250 | K6: ='TenantGuard three-case revenue'!K5*'TenantGuard inputs'!B6 -> 26000 | L6: ='TenantGuard three-case revenue'!L5*'Model inputs'!C9 -> 6000 | M6: ='TenantGuard three-case revenue'!M5*'Model inputs'!C8 -> 73666.667 | N6: ='TenantGuard three-case revenue'!N5*'TenantGuard inputs'!B6 -> 32500 | O6: ='TenantGuard three-case revenue'!O5*'Model inputs'!C9 -> 7500 | P6: ='TenantGuard three-case revenue'!P5*'Model inputs'!C8 -> 92083.333 | Q6: ='TenantGuard three-case revenue'!Q5*'TenantGuard inputs'!B6 -> 39000 | R6: ='TenantGuard three-case revenue'!R5*'Model inputs'!C9 -> 9000 | S6: ='TenantGuard three-case revenue'!S5*'Model inputs'!C8 -> 110500 | T6: ='TenantGuard three-case revenue'!T5*'TenantGuard inputs'!B6 -> 45500 | U6: ='TenantGuard three-case revenue'!U5*'Model inputs'!C9 -> 10500 | V6: ='TenantGuard three-case revenue'!V5*'Model inputs'!C8 -> 128916.67 | W6: ='TenantGuard three-case revenue'!W5*'TenantGuard inputs'!B6 -> 52000 | X6: ='TenantGuard three-case revenue'!X5*'Model inputs'!C9 -> 12000 | Y6: ='TenantGuard three-case revenue'!Y5*'Model inputs'!C8 -> 147333.33 | Z6: ='TenantGuard three-case revenue'!Z5*'TenantGuard inputs'!B6 -> 58500 | AA6: ='TenantGuard three-case revenue'!AA5*'Model inputs'!C9 -> 13500 | AB6: ='TenantGuard three-case revenue'!AB5*'Model inputs'!C8 -> 165750 | AC6: ='TenantGuard three-case revenue'!AC5*'TenantGuard inputs'!B6 -> 65000 | AD6: ='TenantGuard three-case revenue'!AD5*'Model inputs'!C9 -> 15000 | AE6: ='TenantGuard three-case revenue'!AE5*'Model inputs'!C8 -> 184166.67 | AF6: ='TenantGuard three-case revenue'!AF5*'TenantGuard inputs'!B6 -> 71500 | AG6: ='TenantGuard three-case revenue'!AG5*'Model inputs'!C9 -> 16500 | AH6: ='TenantGuard three-case revenue'!AH5*'Model inputs'!C8 -> 202583.33 | AI6: ='TenantGuard three-case revenue'!AI5*'TenantGuard inputs'!B6 -> 78000 | AJ6: ='TenantGuard three-case revenue'!AJ5*'Model inputs'!C9 -> 18000 | AK6: ='TenantGuard three-case revenue'!AK5*'Model inputs'!C8 -> 221000
A7: Compute gross margin | B7: =IFERROR('Model inputs'!D10/'TenantGuard three-case revenue'!B6,"") -> 0.99346154 | C7: =IFERROR('Model inputs'!D12/'TenantGuard three-case revenue'!C6,"") -> 0.98777778 | D7: =IFERROR('Model inputs'!D11/'TenantGuard three-case revenue'!D6,"") -> 0.99529412 | E7: =IFERROR('Model inputs'!E10/'TenantGuard three-case revenue'!E6,"") -> 0.99346154 | F7: =IFERROR('Model inputs'!E12/'TenantGuard three-case revenue'!F6,"") -> 0.98777778 | G7: =IFERROR('Model inputs'!E11/'TenantGuard three-case revenue'!G6,"") -> 0.99529412 | H7: =IFERROR('Model inputs'!F10/'TenantGuard three-case revenue'!H6,"") -> 0.99346154 | I7: =IFERROR('Model inputs'!F12/'TenantGuard three-case revenue'!I6,"") -> 0.98777778 | J7: =IFERROR('Model inputs'!F11/'TenantGuard three-case revenue'!J6,"") -> 0.99529412 | K7: =IFERROR('Model inputs'!G10/'TenantGuard three-case revenue'!K6,"") -> 0.99346154 | L7: =IFERROR('Model inputs'!G12/'TenantGuard three-case revenue'!L6,"") -> 0.98777778 | M7: =IFERROR('Model inputs'!G11/'TenantGuard three-case revenue'!M6,"") -> 0.99529412 | N7: =IFERROR('Model inputs'!H10/'TenantGuard three-case revenue'!N6,"") -> 0.99346154 | O7: =IFERROR('Model inputs'!H12/'TenantGuard three-case revenue'!O6,"") -> 0.98777778 | P7: =IFERROR('Model inputs'!H11/'TenantGuard three-case revenue'!P6,"") -> 0.99529412 | Q7: =IFERROR('Model inputs'!I10/'TenantGuard three-case revenue'!Q6,"") -> 0.99346154 | R7: =IFERROR('Model inputs'!I12/'TenantGuard three-case revenue'!R6,"") -> 0.98777778 | S7: =IFERROR('Model inputs'!I11/'TenantGuard three-case revenue'!S6,"") -> 0.99529412 | T7: =IFERROR('Model inputs'!J10/'TenantGuard three-case revenue'!T6,"") -> 0.99346154 | U7: =IFERROR('Model inputs'!J12/'TenantGuard three-case revenue'!U6,"") -> 0.98777778 | V7: =IFERROR('Model inputs'!J11/'TenantGuard three-case revenue'!V6,"") -> 0.99529412 | W7: =IFERROR('Model inputs'!K10/'TenantGuard three-case revenue'!W6,"") -> 0.99346154 | X7: =IFERROR('Model inputs'!K12/'TenantGuard three-case revenue'!X6,"") -> 0.98777778 | Y7: =IFERROR('Model inputs'!K11/'TenantGuard three-case revenue'!Y6,"") -> 0.99529412 | Z7: =IFERROR('Model inputs'!L10/'TenantGuard three-case revenue'!Z6,"") -> 0.99346154 | AA7: =IFERROR('Model inputs'!L12/'TenantGuard three-case revenue'!AA6,"") -> 0.98777778 | AB7: =IFERROR('Model inputs'!L11/'TenantGuard three-case revenue'!AB6,"") -> 0.99529412 | AC7: =IFERROR('Model inputs'!M10/'TenantGuard three-case revenue'!AC6,"") -> 0.99346154 | AD7: =IFERROR('Model inputs'!M12/'TenantGuard three-case revenue'!AD6,"") -> 0.98777778 | AE7: =IFERROR('Model inputs'!M11/'TenantGuard three-case revenue'!AE6,"") -> 0.99529412 | AF7: =IFERROR('Model inputs'!N10/'TenantGuard three-case revenue'!AF6,"") -> 0.99346154 | AG7: =IFERROR('Model inputs'!N12/'TenantGuard three-case revenue'!AG6,"") -> 0.98777778 | AH7: =IFERROR('Model inputs'!N11/'TenantGuard three-case revenue'!AH6,"") -> 0.99529412 | AI7: =IFERROR('Model inputs'!O10/'TenantGuard three-case revenue'!AI6,"") -> 0.99346154 | AJ7: =IFERROR('Model inputs'!O12/'TenantGuard three-case revenue'!AJ6,"") -> 0.98777778 | AK7: =IFERROR('Model inputs'!O11/'TenantGuard three-case revenue'!AK6,"") -> 0.99529412
A8: TenantGuard ending cash | B8: =IF(IF(DATE(2026,10,1)=DATE(2026,10,1),IF('TenantGuard inputs'!B13="","",'TenantGuard inputs'!B13),IF('Model inputs'!X26="","",'Model inputs'!X26))="",0,IF(DATE(2026,10,1)=DATE(2026,10,1),IF('TenantGuard inputs'!B13="","",'TenantGuard inputs'!B13),IF('Model inputs'!X26="","",'Model inputs'!X26)))+'Model inputs'!D29 -> 856457.5 | C8: =IF(IF(DATE(2026,10,1)=DATE(2026,10,1),IF('Model inputs'!C22="","",'Model inputs'!C22),IF('Model inputs'!X28="","",'Model inputs'!X28))="",0,IF(DATE(2026,10,1)=DATE(2026,10,1),IF('Model inputs'!C22="","",'Model inputs'!C22),IF('Model inputs'!X28="","",'Model inputs'!X28)))+'Model inputs'!D31 -> 851481.67 | D8: =IF(IF(DATE(2026,10,1)=DATE(2026,10,1),IF('Model inputs'!C21="","",'Model inputs'!C21),IF('Model inputs'!X27="","",'Model inputs'!X27))="",0,IF(DATE(2026,10,1)=DATE(2026,10,1),IF('Model inputs'!C21="","",'Model inputs'!C21),IF('Model inputs'!X27="","",'Model inputs'!X27)))+'Model inputs'!D30 -> 868330 | E8: =IF(IF(DATE(2026,11,1)=DATE(2026,10,1),IF('TenantGuard inputs'!B13="","",'TenantGuard inputs'!B13),IF('TenantGuard three-case revenue'!B8="","",'TenantGuard three-case revenue'!B8))="",0,IF(DATE(2026,11,1)=DATE(2026,10,1),IF('TenantGuard inputs'!B13="","",'TenantGuard inputs'!B13),IF('TenantGuard three-case revenue'!B8="","",'TenantGuard three-case revenue'!B8)))+'Model inputs'!E29 -> 819372.5 | F8: =IF(IF(DATE(2026,11,1)=DATE(2026,10,1),IF('Model inputs'!C22="","",'Model inputs'!C22),IF('TenantGuard three-case revenue'!C8="","",'TenantGuard three-case revenue'!C8))="",0,IF(DATE(2026,11,1)=DATE(2026,10,1),IF('Model inputs'!C22="","",'Model inputs'!C22),IF('TenantGuard three-case revenue'!C8="","",'TenantGuard three-case revenue'!C8)))+'Model inputs'!E31 -> 804445 | G8: =IF(IF(DATE(2026,11,1)=DATE(2026,10,1),IF('Model inputs'!C21="","",'Model inputs'!C21),IF('TenantGuard three-case revenue'!D8="","",'TenantGuard three-case revenue'!D8))="",0,IF(DATE(2026,11,1)=DATE(2026,10,1),IF('Model inputs'!C21="","",'Model inputs'!C21),IF('TenantGuard three-case revenue'!D8="","",'TenantGuard three-case revenue'!D8)))+'Model inputs'!E30 -> 854990 | H8: =IF(IF(DATE(2026,12,1)=DATE(2026,10,1),IF('TenantGuard inputs'!B13="","",'TenantGuard inputs'!B13),IF('TenantGuard three-case revenue'!E8="","",'TenantGuard three-case revenue'!E8))="",0,IF(DATE(2026,12,1)=DATE(2026,10,1),IF('TenantGuard inputs'!B13="","",'TenantGuard inputs'!B13),IF('TenantGuard three-case revenue'!E8="","",'TenantGuard three-case revenue'!E8)))+'Model inputs'!F29 -> 788745 | I8: =IF(IF(DATE(2026,12,1)=DATE(2026,10,1),IF('Model inputs'!C22="","",'Model inputs'!C22),IF('TenantGuard three-case revenue'!F8="","",'TenantGuard three-case revenue'!F8))="",0,IF(DATE(2026,12,1)=DATE(2026,10,1),IF('Model inputs'!C22="","",'Model inputs'!C22),IF('TenantGuard three-case revenue'!F8="","",'TenantGuard three-case revenue'!F8)))+'Model inputs'!F31 -> 758890 | J8: =IF(IF(DATE(2026,12,1)=DATE(2026,10,1),IF('Model inputs'!C21="","",'Model inputs'!C21),IF('TenantGuard three-case revenue'!G8="","",'TenantGuard three-case revenue'!G8))="",0,IF(DATE(2026,12,1)=DATE(2026,10,1),IF('Model inputs'!C21="","",'Model inputs'!C21),IF('TenantGuard three-case revenue'!G8="","",'TenantGuard three-case revenue'!G8)))+'Model inputs'!F30 -> 859980 | K8: =IF(IF(DATE(2027,1,1)=DATE(2026,10,1),IF('TenantGuard inputs'!B13="","",'TenantGuard inputs'!B13),IF('TenantGuard three-case revenue'!H8="","",'TenantGuard three-case revenue'!H8))="",0,IF(DATE(2027,1,1)=DATE(2026,10,1),IF('TenantGuard inputs'!B13="","",'TenantGuard inputs'!B13),IF('TenantGuard three-case revenue'!H8="","",'TenantGuard three-case revenue'!H8)))+'Model inputs'!G29 -> 764575 | L8: =IF(IF(DATE(2027,1,1)=DATE(2026,10,1),IF('Model inputs'!C22="","",'Model inputs'!C22),IF('TenantGuard three-case revenue'!I8="","",'TenantGuard three-case revenue'!I8))="",0,IF(DATE(2027,1,1)=DATE(2026,10,1),IF('Model inputs'!C22="","",'Model inputs'!C22),IF('TenantGuard three-case revenue'!I8="","",'TenantGuard three-case revenue'!I8)))+'Model inputs'!G31 -> 714816.67 | M8: =IF(IF(DATE(2027,1,1)=DATE(2026,10,1),IF('Model inputs'!C21="","",'Model inputs'!C21),IF('TenantGuard three-case revenue'!J8="","",'TenantGuard three-case revenue'!J8))="",0,IF(DATE(2027,1,1)=DATE(2026,10,1),IF('Model inputs'!C21="","",'Model inputs'!C21),IF('TenantGuard three-case revenue'!J8="","",'TenantGuard three-case revenue'!J8)))+'Model inputs'!G30 -> 883300 | N8: =IF(IF(DATE(2027,2,1)=DATE(2026,10,1),IF('TenantGuard inputs'!B13="","",'TenantGuard inputs'!B13),IF('TenantGuard three-case revenue'!K8="","",'TenantGuard three-case revenue'!K8))="",0,IF(DATE(2027,2,1)=DATE(2026,10,1),IF('TenantGuard inputs'!B13="","",'TenantGuard inputs'!B13),IF('TenantGuard three-case revenue'!K8="","",'TenantGuard three-case revenue'!K8)))+'Model inputs'!H29 -> 746862.5 | O8: =IF(IF(DATE(2027,2,1)=DATE(2026,10,1),IF('Model inputs'!C22="","",'Model inputs'!C22),IF('TenantGuard three-case revenue'!L8="","",'TenantGuard three-case revenue'!L8))="",0,IF(DATE(2027,2,1)=DATE(2026,10,1),IF('Model inputs'!C22="","",'Model inputs'!C22),IF('TenantGuard three-case revenue'!L8="","",'TenantGuard three-case revenue'!L8)))+'Model inputs'!H31 -> 672225 | P8: =IF(IF(DATE(2027,2,1)=DATE(2026,10,1),IF('Model inputs'!C21="","",'Model inputs'!C21),IF('TenantGuard three-case revenue'!M8="","",'TenantGuard three-case revenue'!M8))="",0,IF(DATE(2027,2,1)=DATE(2026,10,1),IF('Model inputs'!C21="","",'Model inputs'!C21),IF('TenantGuard three-case revenue'!M8="","",'TenantGuard three-case revenue'!M8)))+'Model inputs'!H30 -> 924950 | Q8: =IF(IF(DATE(2027,3,1)=DATE(2026,10,1),IF('TenantGuard inputs'!B13="","",'TenantGuard inputs'!B13),IF('TenantGuard three-case revenue'!N8="","",'TenantGuard three-case revenue'!N8))="",0,IF(DATE(2027,3,1)=DATE(2026,10,1),IF('TenantGuard inputs'!B13="","",'TenantGuard inputs'!B13),IF('TenantGuard three-case revenue'!N8="","",'TenantGuard three-case revenue'!N8)))+'Model inputs'!I29 -> 735607.5 | R8: =IF(IF(DATE(2027,3,1)=DATE(2026,10,1),IF('Model inputs'!C22="","",'Model inputs'!C22),IF('TenantGuard three-case revenue'!O8="","",'TenantGuard three-case revenue'!O8))="",0,IF(DATE(2027,3,1)=DATE(2026,10,1),IF('Model inputs'!C22="","",'Model inputs'!C22),IF('TenantGuard three-case revenue'!O8="","",'TenantGuard three-case revenue'!O8)))+'Model inputs'!I31 -> 631115 | S8: =IF(IF(DATE(2027,3,1)=DATE(2026,10,1),IF('Model inputs'!C21="","",'Model inputs'!C21),IF('TenantGuard three-case revenue'!P8="","",'TenantGuard three-case revenue'!P8))="",0,IF(DATE(2027,3,1)=DATE(2026,10,1),IF('Model inputs'!C21="","",'Model inputs'!C21),IF('TenantGuard three-case revenue'!P8="","",'TenantGuard three-case revenue'!P8)))+'Model inputs'!I30 -> 984930 | T8: =IF(IF(DATE(2027,4,1)=DATE(2026,10,1),IF('TenantGuard inputs'!B13="","",'TenantGuard inputs'!B13),IF('TenantGuard three-case revenue'!Q8="","",'TenantGuard three-case revenue'!Q8))="",0,IF(DATE(2027,4,1)=DATE(2026,10,1),IF('TenantGuard inputs'!B13="","",'TenantGuard inputs'!B13),IF('TenantGuard three-case revenue'!Q8="","",'TenantGuard three-case revenue'!Q8)))+'Model inputs'!J29 -> 730810 | U8: =IF(IF(DATE(2027,4,1)=DATE(2026,10,1),IF('Model inputs'!C22="","",'Model inputs'!C22),IF('TenantGuard three-case revenue'!R8="","",'TenantGuard three-case revenue'!R8))="",0,IF(DATE(2027,4,1)=DATE(2026,10,1),IF('Model inputs'!C22="","",'Model inputs'!C22),IF('TenantGuard three-case revenue'!R8="","",'TenantGuard three-case revenue'!R8)))+'Model inputs'!J31 -> 591486.67 | V8: =IF(IF(DATE(2027,4,1)=DATE(2026,10,1),IF('Model inputs'!C21="","",'Model inputs'!C21),IF('TenantGuard three-case revenue'!S8="","",'TenantGuard three-case revenue'!S8))="",0,IF(DATE(2027,4,1)=DATE(2026,10,1),IF('Model inputs'!C21="","",'Model inputs'!C21),IF('TenantGuard three-case revenue'!S8="","",'TenantGuard three-case revenue'!S8)))+'Model inputs'!J30 -> 1063240 | W8: =IF(IF(DATE(2027,5,1)=DATE(2026,10,1),IF('TenantGuard inputs'!B13="","",'TenantGuard inputs'!B13),IF('TenantGuard three-case revenue'!T8="","",'TenantGuard three-case revenue'!T8))="",0,IF(DATE(2027,5,1)=DATE(2026,10,1),IF('TenantGuard inputs'!B13="","",'TenantGuard inputs'!B13),IF('TenantGuard three-case revenue'!T8="","",'TenantGuard three-case revenue'!T8)))+'Model inputs'!K29 -> 732470 | X8: =IF(IF(DATE(2027,5,1)=DATE(2026,10,1),IF('Model inputs'!C22="","",'Model inputs'!C22),IF('TenantGuard three-case revenue'!U8="","",'TenantGuard three-case revenue'!U8))="",0,IF(DATE(2027,5,1)=DATE(2026,10,1),IF('Model inputs'!C22="","",'Model inputs'!C22),IF('TenantGuard three-case revenue'!U8="","",'TenantGuard three-case revenue'!U8)))+'Model inputs'!K31 -> 553340 | Y8: =IF(IF(DATE(2027,5,1)=DATE(2026,10,1),IF('Model inputs'!C21="","",'Model inputs'!C21),IF('TenantGuard three-case revenue'!V8="","",'TenantGuard three-case revenue'!V8))="",0,IF(DATE(2027,5,1)=DATE(2026,10,1),IF('Model inputs'!C21="","",'Model inputs'!C21),IF('TenantGuard three-case revenue'!V8="","",'TenantGuard three-case revenue'!V8)))+'Model inputs'!K30 -> 1159880 | Z8: =IF(IF(DATE(2027,6,1)=DATE(2026,10,1),IF('TenantGuard inputs'!B13="","",'TenantGuard inputs'!B13),IF('TenantGuard three-case revenue'!W8="","",'TenantGuard three-case revenue'!W8))="",0,IF(DATE(2027,6,1)=DATE(2026,10,1),IF('TenantGuard inputs'!B13="","",'TenantGuard inputs'!B13),IF('TenantGuard three-case revenue'!W8="","",'TenantGuard three-case revenue'!W8)))+'Model inputs'!L29 -> 740587.5 | AA8: =IF(IF(DATE(2027,6,1)=DATE(2026,10,1),IF('Model inputs'!C22="","",'Model inputs'!C22),IF('TenantGuard three-case revenue'!X8="","",'TenantGuard three-case revenue'!X8))="",0,IF(DATE(2027,6,1)=DATE(2026,10,1),IF('Model inputs'!C22="","",'Model inputs'!C22),IF('TenantGuard three-case revenue'!X8="","",'TenantGuard three-case revenue'!X8)))+'Model inputs'!L31 -> 516675 | AB8: =IF(IF(DATE(2027,6,1)=DATE(2026,10,1),IF('Model inputs'!C21="","",'Model inputs'!C21),IF('TenantGuard three-case revenue'!Y8="","",'TenantGuard three-case revenue'!Y8))="",0,IF(DATE(2027,6,1)=DATE(2026,10,1),IF('Model inputs'!C21="","",'Model inputs'!C21),IF('TenantGuard three-case revenue'!Y8="","",'TenantGuard three-case revenue'!Y8)))+'Model inputs'!L30 -> 1274850 | AC8: =IF(IF(DATE(2027,7,1)=DATE(2026,10,1),IF('TenantGuard inputs'!B13="","",'TenantGuard inputs'!B13),IF('TenantGuard three-case revenue'!Z8="","",'TenantGuard three-case revenue'!Z8))="",0,IF(DATE(2027,7,1)=DATE(2026,10,1),IF('TenantGuard inputs'!B13="","",'TenantGuard inputs'!B13),IF('TenantGuard three-case revenue'!Z8="","",'TenantGuard three-case revenue'!Z8)))+'Model inputs'!M29 -> 755162.5 | AD8: =IF(IF(DATE(2027,7,1)=DATE(2026,10,1),IF('Model inputs'!C22="","",'Model inputs'!C22),IF('TenantGuard three-case revenue'!AA8="","",'TenantGuard three-case revenue'!AA8))="",0,IF(DATE(2027,7,1)=DATE(2026,10,1),IF('Model inputs'!C22="","",'Model inputs'!C22),IF('TenantGuard three-case revenue'!AA8="","",'TenantGuard three-case revenue'!AA8)))+'Model inputs'!M31 -> 481491.67 | AE8: =IF(IF(DATE(2027,7,1)=DATE(2026,10,1),IF('Model inputs'!C21="","",'Model inputs'!C21),IF('TenantGuard three-case revenue'!AB8="","",'TenantGuard three-case revenue'!AB8))="",0,IF(DATE(2027,7,1)=DATE(2026,10,1),IF('Model inputs'!C21="","",'Model inputs'!C21),IF('TenantGuard three-case revenue'!AB8="","",'TenantGuard three-case revenue'!AB8)))+'Model inputs'!M30 -> 1408150 | AF8: =IF(IF(DATE(2027,8,1)=DATE(2026,10,1),IF('TenantGuard inputs'!B13="","",'TenantGuard inputs'!B13),IF('TenantGuard three-case revenue'!AC8="","",'TenantGuard three-case revenue'!AC8))="",0,IF(DATE(2027,8,1)=DATE(2026,10,1),IF('TenantGuard inputs'!B13="","",'TenantGuard inputs'!B13),IF('TenantGuard three-case revenue'!AC8="","",'TenantGuard three-case revenue'!AC8)))+'Model inputs'!N29 -> 776195 | AG8: =IF(IF(DATE(2027,8,1)=DATE(2026,10,1),IF('Model inputs'!C22="","",'Model inputs'!C22),IF('TenantGuard three-case revenue'!AD8="","",'TenantGuard three-case revenue'!AD8))="",0,IF(DATE(2027,8,1)=DATE(2026,10,1),IF('Model inputs'!C22="","",'Model inputs'!C22),IF('TenantGuard three-case revenue'!AD8="","",'TenantGuard three-case revenue'!AD8)))+'Model inputs'!N31 -> 447790 | AH8: =IF(IF(DATE(2027,8,1)=DATE(2026,10,1),IF('Model inputs'!C21="","",'Model inputs'!C21),IF('TenantGuard three-case revenue'!AE8="","",'TenantGuard three-case revenue'!AE8))="",0,IF(DATE(2027,8,1)=DATE(2026,10,1),IF('Model inputs'!C21="","",'Model inputs'!C21),IF('TenantGuard three-case revenue'!AE8="","",'TenantGuard three-case revenue'!AE8)))+'Model inputs'!N30 -> 1559780 | AI8: =IF(IF(DATE(2027,9,1)=DATE(2026,10,1),IF('TenantGuard inputs'!B13="","",'TenantGuard inputs'!B13),IF('TenantGuard three-case revenue'!AF8="","",'TenantGuard three-case revenue'!AF8))="",0,IF(DATE(2027,9,1)=DATE(2026,10,1),IF('TenantGuard inputs'!B13="","",'TenantGuard inputs'!B13),IF('TenantGuard three-case revenue'!AF8="","",'TenantGuard three-case revenue'!AF8)))+'Model inputs'!O29 -> 803685 | AJ8: =IF(IF(DATE(2027,9,1)=DATE(2026,10,1),IF('Model inputs'!C22="","",'Model inputs'!C22),IF('TenantGuard three-case revenue'!AG8="","",'TenantGuard three-case revenue'!AG8))="",0,IF(DATE(2027,9,1)=DATE(2026,10,1),IF('Model inputs'!C22="","",'Model inputs'!C22),IF('TenantGuard three-case revenue'!AG8="","",'TenantGuard three-case revenue'!AG8)))+'Model inputs'!O31 -> 415570 | AK8: =IF(IF(DATE(2027,9,1)=DATE(2026,10,1),IF('Model inputs'!C21="","",'Model inputs'!C21),IF('TenantGuard three-case revenue'!AH8="","",'TenantGuard three-case revenue'!AH8))="",0,IF(DATE(2027,9,1)=DATE(2026,10,1),IF('Model inputs'!C21="","",'Model inputs'!C21),IF('TenantGuard three-case revenue'!AH8="","",'TenantGuard three-case revenue'!AH8)))+'Model inputs'!O30 -> 1729740

Sheet TenantGuard inputs
A1: TenantGuard inputs
A2: TenantGuard — Business Plan · Main Scenario
A4: Variable / dimension | B4: Value
A5: Month 12 customers | B5: =120 -> 120
A6: Blended monthly ARPA | B6: =650 -> 650
A7: Attempts per completed fix | B7: =2.5 -> 2.5
A8: Fixes per customer per month | B8: =100 -> 100
A9: Token cost per attempt | B9: =0.005 -> 0.005
A10: Compute cost per completed fix | B10: =0.03 -> 0.03
A11: Monthly customer churn | B11: =0.01 -> 0.01
A12: Fixed monthly operating spend | B12: =50000 -> 50000
A13: Launch cash | B13: =900000 -> 900000

Sheet TenantGuard launch settings
A1: TenantGuard launch settings
A2: TenantGuard — Business Plan · Main Scenario
A4: Variable / dimension | B4: Value
A5: Launch customers | B5: =0 -> 0
A6: Customer ramp months | B6: =12 -> 12

Sheet Model inputs
A1: Model inputs
A2: Integration values are aggregated snapshots; raw source records are not included.
A4: Variables
A5: Variable / segment | B5: Value | C5: Value | D5: 2026-10 | E5: 2026-11 | F5: 2026-12 | G5: 2027-01 | H5: 2027-02 | I5: 2027-03 | J5: 2027-04 | K5: 2027-05 | L5: 2027-06 | M5: 2027-07 | N5: 2027-08 | O5: 2027-09 | P5: 2026-01 | Q5: 2026-02 | R5: 2026-03 | S5: 2026-04 | T5: 2026-05 | U5: 2026-06 | V5: 2026-07 | W5: 2026-08 | X5: 2026-09 | Y5: 2027-10 | Z5: 2027-11 | AA5: 2027-12 | AB5: 2028-01 | AC5: 2028-02 | AD5: 2028-03 | AE5: 2028-04 | AF5: 2028-05 | AG5: 2028-06 | AH5: 2028-07 | AI5: 2028-08 | AJ5: 2028-09 | AK5: 2028-10 | AL5: 2028-11 | AM5: 2028-12 | AN5: 2029-01 | AO5: 2029-02 | AP5: 2029-03 | AQ5: 2029-04 | AR5: 2029-05 | AS5: 2029-06 | AT5: 2029-07 | AU5: 2029-08 | AV5: 2029-09
A6: Blended monthly ARPA · TenantGuard unit economics · Main Scenario | B6: ='TenantGuard inputs'!B6 -> 650
A7: Blended monthly ARPA · TenantGuard three-case revenue ramp · Main Scenario | C7: ='TenantGuard inputs'!B6 -> 650
A8: Blended monthly ARPA · TenantGuard — High | C8: =850 -> 850
A9: Blended monthly ARPA · TenantGuard — Low | C9: =450 -> 450
A10: Compute gross profit · Main Scenario | D10: ='Model inputs'!D32-'Model inputs'!D56 -> 6457.5 | E10: ='Model inputs'!E32-'Model inputs'!E56 -> 12915 | F10: ='Model inputs'!F32-'Model inputs'!F56 -> 19372.5 | G10: ='Model inputs'!G32-'Model inputs'!G56 -> 25830 | H10: ='Model inputs'!H32-'Model inputs'!H56 -> 32287.5 | I10: ='Model inputs'!I32-'Model inputs'!I56 -> 38745 | J10: ='Model inputs'!J32-'Model inputs'!J56 -> 45202.5 | K10: ='Model inputs'!K32-'Model inputs'!K56 -> 51660 | ... O10: ='Model inputs'!O32-'Model inputs'!O56 -> 77490
A11: Compute gross profit · TenantGuard — High | D11: ='Model inputs'!D62-'Model inputs'!D57 -> 18330 | E11: ='Model inputs'!E62-'Model inputs'!E57 -> 36660 | F11: ='Model inputs'!F62-'Model inputs'!F57 -> 54990 | G11: ='Model inputs'!G62-'Model inputs'!G57 -> 73320 | H11: ='Model inputs'!H62-'Model inputs'!H57 -> 91650 | I11: ='Model inputs'!I62-'Model inputs'!I57 -> 109980 | J11: ='Model inputs'!J62-'Model inputs'!J57 -> 128310 | K11: ='Model inputs'!K62-'Model inputs'!K57 -> 146640 | ... O11: ='Model inputs'!O62-'Model inputs'!O57 -> 219960
A12: Compute gross profit · TenantGuard — Low | D12: ='Model inputs'!D63-'Model inputs'!D58 -> 1481.6667 | E12: ='Model inputs'!E63-'Model inputs'!E58 -> 2963.3333 | F12: ='Model inputs'!F63-'Model inputs'!F58 -> 4445 | G12: ='Model inputs'!G63-'Model inputs'!G58 -> 5926.6667 | H12: ='Model inputs'!H63-'Model inputs'!H58 -> 7408.3333 | I12: ='Model inputs'!I63-'Model inputs'!I58 -> 8890 | J12: ='Model inputs'!J63-'Model inputs'!J58 -> 10371.667 | K12: ='Model inputs'!K63-'Model inputs'!K58 -> 11853.333 | ... O12: ='Model inputs'!O63-'Model inputs'!O58 -> 17780
A13: Customer losses · TenantGuard three-case revenue ramp · Main Scenario | D13: ='Model inputs'!D23*'Model inputs'!C51 -> 0 | E13: ='Model inputs'!E23*'Model inputs'!C51 -> 0.1 | F13: ='Model inputs'!F23*'Model inputs'!C51 -> 0.2 | G13: ='Model inputs'!G23*'Model inputs'!C51 -> 0.3 | H13: ='Model inputs'!H23*'Model inputs'!C51 -> 0.4 | I13: ='Model inputs'!I23*'Model inputs'!C51 -> 0.5 | J13: ='Model inputs'!J23*'Model inputs'!C51 -> 0.6 | K13: ='Model inputs'!K23*'Model inputs'!C51 -> 0.7 | L13: ='Model inputs'!L23*'Model inputs'!C51 -> 0.8 | M13: ='Model inputs'!M23*'Model inputs'!C51 -> 0.9 | N13: ='Model inputs'!N23*'Model inputs'!C51 -> 1 | O13: ='Model inputs'!O23*'Model inputs'!C51 -> 1.1 | P13: 0 | Q13: 0 | R13: 0 | S13: 0 | T13: 0 | U13: 0 | V13: 0 | W13: 0 | X13: 0
A14: Customer losses · TenantGuard — High | D14: ='Model inputs'!D24*'Model inputs'!C52 -> 0 | E14: ='Model inputs'!E24*'Model inputs'!C52 -> 0.21666667 | F14: ='Model inputs'!F24*'Model inputs'!C52 -> 0.43333333 | G14: ='Model inputs'!G24*'Model inputs'!C52 -> 0.65 | H14: ='Model inputs'!H24*'Model inputs'!C52 -> 0.86666667 | I14: ='Model inputs'!I24*'Model inputs'!C52 -> 1.0833333 | J14: ='Model inputs'!J24*'Model inputs'!C52 -> 1.3 | K14: ='Model inputs'!K24*'Model inputs'!C52 -> 1.5166667 | L14: ='Model inputs'!L24*'Model inputs'!C52 -> 1.7333333 | M14: ='Model inputs'!M24*'Model inputs'!C52 -> 1.95 | N14: ='Model inputs'!N24*'Model inputs'!C52 -> 2.1666667 | O14: ='Model inputs'!O24*'Model inputs'!C52 -> 2.3833333 | X14: 0
A15: Customer losses · TenantGuard — Low | D15: ='Model inputs'!D25*'Model inputs'!C53 -> 0 | E15: ='Model inputs'!E25*'Model inputs'!C53 -> 0.033333333 | F15: ='Model inputs'!F25*'Model inputs'!C53 -> 0.066666667 | G15: ='Model inputs'!G25*'Model inputs'!C53 -> 0.1 | H15: ='Model inputs'!H25*'Model inputs'!C53 -> 0.13333333 | I15: ='Model inputs'!I25*'Model inputs'!C53 -> 0.16666667 | J15: ='Model inputs'!J25*'Model inputs'!C53 -> 0.2 | K15: ='Model inputs'!K25*'Model inputs'!C53 -> 0.23333333 | L15: ='Model inputs'!L25*'Model inputs'!C53 -> 0.26666667 | M15: ='Model inputs'!M25*'Model inputs'!C53 -> 0.3 | N15: ='Model inputs'!N25*'Model inputs'!C53 -> 0.33333333 | O15: ='Model inputs'!O25*'Model inputs'!C53 -> 0.36666667 | X15: 0
A16: Gross customer additions · TenantGuard three-case revenue ramp · Main Scenario | D16: =IF(IF(IF(IF(ISERROR('Model inputs'!D42<='Model inputs'!C36),'Model inputs'!D42<='Model inputs'!C36,IF(OR('Model inputs'!D42="",'Model inputs'!C36=""),"",'Model inputs'!D42<='Model inputs'!C36))="",FALSE,IF(ISERROR('Model inputs'!D42<='Model inputs'!C36),'Model inputs'!D42<='Model inputs'!C36,IF(OR('Model inputs'!D42="",'Model inputs'!C36=""),"",'Model inputs'!D42<='Model inputs'!C36))),('Model inputs'!C48-'Model inputs'!C45)/'Model inputs'!C36,0)="",0,IF(IF(IF(ISERROR('Model inputs'!D42<='Model inputs'!C36),'Model inputs'!D42<='Model inputs'!C36,IF(OR('Model inputs'!D42="",'Model inputs'!C36=""),"",'Model inputs'!D42<='Model inputs'!C36))="",FALSE,IF(ISERROR('Model inputs'!D42<='Model inputs'!C36),'Model inputs'!D42<='Model inputs'!C36,IF(OR('Model inputs'!D42="",'Model inputs'!C36=""),"",'Model inputs'!D42<='Model inputs'!C36))),('Model inputs'!C48-'Model inputs'!C45)/'Model inputs'!C36,0))+'Model inputs'!D23*'Model inputs'!C51 -> 10 | E16: =IF(IF(IF(IF(ISERROR('Model inputs'!E42<='Model inputs'!C36),'Model inputs'!E42<='Model inputs'!C36,IF(OR('Model inputs'!E42="",'Model inputs'!C36=""),"",'Model inputs'!E42<='Model inputs'!C36))="",FALSE,IF(ISERROR('Model inputs'!E42<='Model inputs'!C36),'Model inputs'!E42<='Model inputs'!C36,IF(OR('Model inputs'!E42="",'Model inputs'!C36=""),"",'Model inputs'!E42<='Model inputs'!C36))),('Model inputs'!C48-'Model inputs'!C45)/'Model inputs'!C36,0)="",0,IF(IF(IF(ISERROR('Model inputs'!E42<='Model inputs'!C36),'Model inputs'!E42<='Model inputs'!C36,IF(OR('Model inputs'!E42="",'Model inputs'!C36=""),"",'Model inputs'!E42<='Model inputs'!C36))="",FALSE,IF(ISERROR('Model inputs'!E42<='Model inputs'!C36),'Model inputs'!E42<='Model inputs'!C36,IF(OR('Model inputs'!E42="",'Model inputs'!C36=""),"",'Model inputs'!E42<='Model inputs'!C36))),('Model inputs'!C48-'Model inputs'!C45)/'Model inputs'!C36,0))+'Model inputs'!E23*'Model inputs'!C51 -> 10.1 | F16: =IF(IF(IF(IF(ISERROR('Model inputs'!F42<='Model inputs'!C36),'Model inputs'!F42<='Model inputs'!C36,IF(OR('Model inputs'!F42="",'Model inputs'!C36=""),"",'Model inputs'!F42<='Model inputs'!C36))="",FALSE,IF(ISERROR('Model inputs'!F42<='Model inputs'!C36),'Model inputs'!F42<='Model inputs'!C36,IF(OR('Model inputs'!F42="",'Model inputs'!C36=""),"",'Model inputs'!F42<='Model inputs'!C36))),('Model inputs'!C48-'Model inputs'!C45)/'Model inputs'!C36,0)="",0,IF(IF(IF(ISERROR('Model inputs'!F42<='Model inputs'!C36),'Model inputs'!F42<='Model inputs'!C36,IF(OR('Model inputs'!F42="",'Model inputs'!C36=""),"",'Model inputs'!F42<='Model inputs'!C36))="",FALSE,IF(ISERROR('Model inputs'!F42<='Model inputs'!C36),'Model inputs'!F42<='Model inputs'!C36,IF(OR('Model inputs'!F42="",'Model inputs'!C36=""),"",'Model inputs'!F42<='Model inputs'!C36))),('Model inputs'!C48-'Model inputs'!C45)/'Model inputs'!C36,0))+'Model inputs'!F23*'Model inputs'!C51 -> 10.2 | G16: =IF(IF(IF(IF(ISERROR('Model inputs'!G42<='Model inputs'!C36),'Model inputs'!G42<='Model inputs'!C36,IF(OR('Model inputs'!G42="",'Model inputs'!C36=""),"",'Model inputs'!G42<='Model inputs'!C36))="",FALSE,IF(ISERROR('Model inputs'!G42<='Model inputs'!C36),'Model inputs'!G42<='Model inputs'!C36,IF(OR('Model inputs'!G42="",'Model inputs'!C36=""),"",'Model inputs'!G42<='Model inputs'!C36))),('Model inputs'!C48-'Model inputs'!C45)/'Model inputs'!C36,0)="",0,IF(IF(IF(ISERROR('Model inputs'!G42<='Model inputs'!C36),'Model inputs'!G42<='Model inputs'!C36,IF(OR('Model inputs'!G42="",'Model inputs'!C36=""),"",'Model inputs'!G42<='Model inputs'!C36))="",FALSE,IF(ISERROR('Model inputs'!G42<='Model inputs'!C36),'Model inputs'!G42<='Model inputs'!C36,IF(OR('Model inputs'!G42="",'Model inputs'!C36=""),"",'Model inputs'!G42<='Model inputs'!C36))),('Model inputs'!C48-'Model inputs'!C45)/'Model inputs'!C36,0))+'Model inputs'!G23*'Model inputs'!C51 -> 10.3 | H16: =IF(IF(IF(IF(ISERROR('Model inputs'!H42<='Model inputs'!C36),'Model inputs'!H42<='Model inputs'!C36,IF(OR('Model inputs'!H42="",'Model inputs'!C36=""),"",'Model inputs'!H42<='Model inputs'!C36))="",FALSE,IF(ISERROR('Model inputs'!H42<='Model inputs'!C36),'Model inputs'!H42<='Model inputs'!C36,IF(OR('Model inputs'!H42="",'Model inputs'!C36=""),"",'Model inputs'!H42<='Model inputs'!C36))),('Model inputs'!C48-'Model inputs'!C45)/'Model inputs'!C36,0)="",0,IF(IF(IF(ISERROR('Model inputs'!H42<='Model inputs'!C36),'Model inputs'!H42<='Model inputs'!C36,IF(OR('Model inputs'!H42="",'Model inputs'!C36=""),"",'Model inputs'!H42<='Model inputs'!C36))="",FALSE,IF(ISERROR('Model inputs'!H42<='Model inputs'!C36),'Model inputs'!H42<='Model inputs'!C36,IF(OR('Model inputs'!H42="",'Model inputs'!C36=""),"",'Model inputs'!H42<='Model inputs'!C36))),('Model inputs'!C48-'Model inputs'!C45)/'Model inputs'!C36,0))+'Model inputs'!H23*'Model inputs'!C51 -> 10.4 | I16: =IF(IF(IF(IF(ISERROR('Model inputs'!I42<='Model inputs'!C36),'Model inputs'!I42<='Model inputs'!C36,IF(OR('Model inputs'!I42="",'Model inputs'!C36=""),"",'Model inputs'!I42<='Model inputs'!C36))="",FALSE,IF(ISERROR('Model inputs'!I42<='Model inputs'!C36),'Model inputs'!I42<='Model inputs'!C36,IF(OR('Model inputs'!I42="",'Model inputs'!C36=""),"",'Model inputs'!I42<='Model inputs'!C36))),('Model inputs'!C48-'Model inputs'!C45)/'Model inputs'!C36,0)="",0,IF(IF(IF(ISERROR('Model inputs'!I42<='Model inputs'!C36),'Model inputs'!I42<='Model inputs'!C36,IF(OR('Model inputs'!I42="",'Model inputs'!C36=""),"",'Model inputs'!I42<='Model inputs'!C36))="",FALSE,IF(ISERROR('Model inputs'!I42<='Model inputs'!C36),'Model inputs'!I42<='Model inputs'!C36,IF(OR('Model inputs'!I42="",'Model inputs'!C36=""),"",'Model inputs'!I42<='Model inputs'!C36))),('Model inputs'!C48-'Model inputs'!C45)/'Model inputs'!C36,0))+'Model inputs'!I23*'Model inputs'!C51 -> 10.5 | J16: =IF(IF(IF(IF(ISERROR('Model inputs'!J42<='Model inputs'!C36),'Model inputs'!J42<='Model inputs'!C36,IF(OR('Model inputs'!J42="",'Model inputs'!C36=""),"",'Model inputs'!J42<='Model inputs'!C36))="",FALSE,IF(ISERROR('Model inputs'!J42<='Model inputs'!C36),'Model inputs'!J42<='Model inputs'!C36,IF(OR('Model inputs'!J42="",'Model inputs'!C36=""),"",'Model inputs'!J42<='Model inputs'!C36))),('Model inputs'!C48-'Model inputs'!C45)/'Model inputs'!C36,0)="",0,IF(IF(IF(ISERROR('Model inputs'!J42<='Model inputs'!C36),'Model inputs'!J42<='Model inputs'!C36,IF(OR('Model inputs'!J42="",'Model inputs'!C36=""),"",'Model inputs'!J42<='Model inputs'!C36))="",FALSE,IF(ISERROR('Model inputs'!J42<='Model inputs'!C36),'Model inputs'!J42<='Model inputs'!C36,IF(OR('Model inputs'!J42="",'Model inputs'!C36=""),"",'Model inputs'!J42<='Model inputs'!C36))),('Model inputs'!C48-'Model inputs'!C45)/'Model inputs'!C36,0))+'Model inputs'!J23*'Model inputs'!C51 -> 10.6 | K16: =IF(IF(IF(IF(ISERROR('Model inputs'!K42<='Model inputs'!C36),'Model inputs'!K42<='Model inputs'!C36,IF(OR('Model inputs'!K42="",'Model inputs'!C36=""),"",'Model inputs'!K42<='Model inputs'!C36))="",FALSE,IF(ISERROR('Model inputs'!K42<='Model inputs'!C36),'Model inputs'!K42<='Model inputs'!C36,IF(OR('Model inputs'!K42="",'Model inputs'!C36=""),"",'Model inputs'!K42<='Model inputs'!C36))),('Model inputs'!C48-'Model inputs'!C45)/'Model inputs'!C36,0)="",0,IF(IF(IF(ISERROR('Model inputs'!K42<='Model inputs'!C36),'Model inputs'!K42<='Model inputs'!C36,IF(OR('Model inputs'!K42="",'Model inputs'!C36=""),"",'Model inputs'!K42<='Model inputs'!C36))="",FALSE,IF(ISERROR('Model inputs'!K42<='Model inputs'!C36),'Model inputs'!K42<='Model inputs'!C36,IF(OR('Model inputs'!K42="",'Model inputs'!C36=""),"",'Model inputs'!K42<='Model inputs'!C36))),('Model inputs'!C48-'Model inputs'!C45)/'Model inputs'!C36,0))+'Model inputs'!K23*'Model inputs'!C51 -> 10.7 | L16: =IF(IF(IF(IF(ISERROR('Model inputs'!L42<='Model inputs'!C36),'Model inputs'!L42<='Model inputs'!C36,IF(OR('Model inputs'!L42="",'Model inputs'!C36=""),"",'Model inputs'!L42<='Model inputs'!C36))="",FALSE,IF(ISERROR('Model inputs'!L42<='Model inputs'!C36),'Model inputs'!L42<='Model inputs'!C36,IF(OR('Model inputs'!L42="",'Model inputs'!C36=""),"",'Model inputs'!L42<='Model inputs'!C36))),('Model inputs'!C48-'Model inputs'!C45)/'Model inputs'!C36,0)="",0,IF(IF(IF(ISERROR('Model inputs'!L42<='Model inputs'!C36),'Model inputs'!L42<='Model inputs'!C36,IF(OR('Model inputs'!L42="",'Model inputs'!C36=""),"",'Model inputs'!L42<='Model inputs'!C36))="",FALSE,IF(ISERROR('Model inputs'!L42<='Model inputs'!C36),'Model inputs'!L42<='Model inputs'!C36,IF(OR('Model inputs'!L42="",'Model inputs'!C36=""),"",'Model inputs'!L42<='Model inputs'!C36))),('Model inputs'!C48-'Model inputs'!C45)/'Model inputs'!C36,0))+'Model inputs'!L23*'Model inputs'!C51 -> 10.8 | M16: =IF(IF(IF(IF(ISERROR('Model inputs'!M42<='Model inputs'!C36),'Model inputs'!M42<='Model inputs'!C36,IF(OR('Model inputs'!M42="",'Model inputs'!C36=""),"",'Model inputs'!M42<='Model inputs'!C36))="",FALSE,IF(ISERROR('Model inputs'!M42<='Model inputs'!C36),'Model inputs'!M42<='Model inputs'!C36,IF(OR('Model inputs'!M42="",'Model inputs'!C36=""),"",'Model inputs'!M42<='Model inputs'!C36))),('Model inputs'!C48-'Model inputs'!C45)/'Model inputs'!C36,0)="",0,IF(IF(IF(ISERROR('Model inputs'!M42<='Model inputs'!C36),'Model inputs'!M42<='Model inputs'!C36,IF(OR('Model inputs'!M42="",'Model inputs'!C36=""),"",'Model inputs'!M42<='Model inputs'!C36))="",FALSE,IF(ISERROR('Model inputs'!M42<='Model inputs'!C36),'Model inputs'!M42<='Model inputs'!C36,IF(OR('Model inputs'!M42="",'Model inputs'!C36=""),"",'Model inputs'!M42<='Model inputs'!C36))),('Model inputs'!C48-'Model inputs'!C45)/'Model inputs'!C36,0))+'Model inputs'!M23*'Model inputs'!C51 -> 10.9 | N16: =IF(IF(IF(IF(ISERROR('Model inputs'!N42<='Model inputs'!C36),'Model inputs'!N42<='Model inputs'!C36,IF(OR('Model inputs'!N42="",'Model inputs'!C36=""),"",'Model inputs'!N42<='Model inputs'!C36))="",FALSE,IF(ISERROR('Model inputs'!N42<='Model inputs'!C36),'Model inputs'!N42<='Model inputs'!C36,IF(OR('Model inputs'!N42="",'Model inputs'!C36=""),"",'Model inputs'!N42<='Model inputs'!C36))),('Model inputs'!C48-'Model inputs'!C45)/'Model inputs'!C36,0)="",0,IF(IF(IF(ISERROR('Model inputs'!N42<='Model inputs'!C36),'Model inputs'!N42<='Model inputs'!C36,IF(OR('Model inputs'!N42="",'Model inputs'!C36=""),"",'Model inputs'!N42<='Model inputs'!C36))="",FALSE,IF(ISERROR('Model inputs'!N42<='Model inputs'!C36),'Model inputs'!N42<='Model inputs'!C36,IF(OR('Model inputs'!N42="",'Model inputs'!C36=""),"",'Model inputs'!N42<='Model inputs'!C36))),('Model inputs'!C48-'Model inputs'!C45)/'Model inputs'!C36,0))+'Model inputs'!N23*'Model inputs'!C51 -> 11 | O16: =IF(IF(IF(IF(ISERROR('Model inputs'!O42<='Model inputs'!C36),'Model inputs'!O42<='Model inputs'!C36,IF(OR('Model inputs'!O42="",'Model inputs'!C36=""),"",'Model inputs'!O42<='Model inputs'!C36))="",FALSE,IF(ISERROR('Model inputs'!O42<='Model inputs'!C36),'Model inputs'!O42<='Model inputs'!C36,IF(OR('Model inputs'!O42="",'Model inputs'!C36=""),"",'Model inputs'!O42<='Model inputs'!C36))),('Model inputs'!C48-'Model inputs'!C45)/'Model inputs'!C36,0)="",0,IF(IF(IF(ISERROR('Model inputs'!O42<='Model inputs'!C36),'Model inputs'!O42<='Model inputs'!C36,IF(OR('Model inputs'!O42="",'Model inputs'!C36=""),"",'Model inputs'!O42<='Model inputs'!C36))="",FALSE,IF(ISERROR('Model inputs'!O42<='Model inputs'!C36),'Model inputs'!O42<='Model inputs'!C36,IF(OR('Model inputs'!O42="",'Model inputs'!C36=""),"",'Model inputs'!O42<='Model inputs'!C36))),('Model inputs'!C48-'Model inputs'!C45)/'Model inputs'!C36,0))+'Model inputs'!O23*'Model inputs'!C51 -> 11.1 | P16: 0 | Q16: 0 | R16: 0 | S16: 0 | T16: 0 | U16: 0 | V16: 0 | W16: 0 | X16: 0
A17: Gross customer additions · TenantGuard — High | D17: =IF(IF(IF(IF(ISERROR('Model inputs'!D43<='Model inputs'!C37),'Model inputs'!D43<='Model inputs'!C37,IF(OR('Model inputs'!D43="",'Model inputs'!C37=""),"",'Model inputs'!D43<='Model inputs'!C37))="",FALSE,IF(ISERROR('Model inputs'!D43<='Model inputs'!C37),'Model inputs'!D43<='Model inputs'!C37,IF(OR('Model inputs'!D43="",'Model inputs'!C37=""),"",'Model inputs'!D43<='Model inputs'!C37))),('Model inputs'!C49-'Model inputs'!C46)/'Model inputs'!C37,0)="",0,IF(IF(IF(ISERROR('Model inputs'!D43<='Model inputs'!C37),'Model inputs'!D43<='Model inputs'!C37,IF(OR('Model inputs'!D43="",'Model inputs'!C37=""),"",'Model inputs'!D43<='Model inputs'!C37))="",FALSE,IF(ISERROR('Model inputs'!D43<='Model inputs'!C37),'Model inputs'!D43<='Model inputs'!C37,IF(OR('Model inputs'!D43="",'Model inputs'!C37=""),"",'Model inputs'!D43<='Model inputs'!C37))),('Model inputs'!C49-'Model inputs'!C46)/'Model inputs'!C37,0))+'Model inputs'!D24*'Model inputs'!C52 -> 21.666667 | E17: =IF(IF(IF(IF(ISERROR('Model inputs'!E43<='Model inputs'!C37),'Model inputs'!E43<='Model inputs'!C37,IF(OR('Model inputs'!E43="",'Model inputs'!C37=""),"",'Model inputs'!E43<='Model inputs'!C37))="",FALSE,IF(ISERROR('Model inputs'!E43<='Model inputs'!C37),'Model inputs'!E43<='Model inputs'!C37,IF(OR('Model inputs'!E43="",'Model inputs'!C37=""),"",'Model inputs'!E43<='Model inputs'!C37))),('Model inputs'!C49-'Model inputs'!C46)/'Model inputs'!C37,0)="",0,IF(IF(IF(ISERROR('Model inputs'!E43<='Model inputs'!C37),'Model inputs'!E43<='Model inputs'!C37,IF(OR('Model inputs'!E43="",'Model inputs'!C37=""),"",'Model inputs'!E43<='Model inputs'!C37))="",FALSE,IF(ISERROR('Model inputs'!E43<='Model inputs'!C37),'Model inputs'!E43<='Model inputs'!C37,IF(OR('Model inputs'!E43="",'Model inputs'!C37=""),"",'Model inputs'!E43<='Model inputs'!C37))),('Model inputs'!C49-'Model inputs'!C46)/'Model inputs'!C37,0))+'Model inputs'!E24*'Model inputs'!C52 -> 21.883333 | F17: =IF(IF(IF(IF(ISERROR('Model inputs'!F43<='Model inputs'!C37),'Model inputs'!F43<='Model inputs'!C37,IF(OR('Model inputs'!F43="",'Model inputs'!C37=""),"",'Model inputs'!F43<='Model inputs'!C37))="",FALSE,IF(ISERROR('Model inputs'!F43<='Model inputs'!C37),'Model inputs'!F43<='Model inputs'!C37,IF(OR('Model inputs'!F43="",'Model inputs'!C37=""),"",'Model inputs'!F43<='Model inputs'!C37))),('Model inputs'!C49-'Model inputs'!C46)/'Model inputs'!C37,0)="",0,IF(IF(IF(ISERROR('Model inputs'!F43<='Model inputs'!C37),'Model inputs'!F43<='Model inputs'!C37,IF(OR('Model inputs'!F43="",'Model inputs'!C37=""),"",'Model inputs'!F43<='Model inputs'!C37))="",FALSE,IF(ISERROR('Model inputs'!F43<='Model inputs'!C37),'Model inputs'!F43<='Model inputs'!C37,IF(OR('Model inputs'!F43="",'Model inputs'!C37=""),"",'Model inputs'!F43<='Model inputs'!C37))),('Model inputs'!C49-'Model inputs'!C46)/'Model inputs'!C37,0))+'Model inputs'!F24*'Model inputs'!C52 -> 22.1 | G17: =IF(IF(IF(IF(ISERROR('Model inputs'!G43<='Model inputs'!C37),'Model inputs'!G43<='Model inputs'!C37,IF(OR('Model inputs'!G43="",'Model inputs'!C37=""),"",'Model inputs'!G43<='Model inputs'!C37))="",FALSE,IF(ISERROR('Model inputs'!G43<='Model inputs'!C37),'Model inputs'!G43<='Model inputs'!C37,IF(OR('Model inputs'!G43="",'Model inputs'!C37=""),"",'Model inputs'!G43<='Model inputs'!C37))),('Model inputs'!C49-'Model inputs'!C46)/'Model inputs'!C37,0)="",0,IF(IF(IF(ISERROR('Model inputs'!G43<='Model inputs'!C37),'Model inputs'!G43<='Model inputs'!C37,IF(OR('Model inputs'!G43="",'Model inputs'!C37=""),"",'Model inputs'!G43<='Model inputs'!C37))="",FALSE,IF(ISERROR('Model inputs'!G43<='Model inputs'!C37),'Model inputs'!G43<='Model inputs'!C37,IF(OR('Model inputs'!G43="",'Model inputs'!C37=""),"",'Model inputs'!G43<='Model inputs'!C37))),('Model inputs'!C49-'Model inputs'!C46)/'Model inputs'!C37,0))+'Model inputs'!G24*'Model inputs'!C52 -> 22.316667 | H17: =IF(IF(IF(IF(ISERROR('Model inputs'!H43<='Model inputs'!C37),'Model inputs'!H43<='Model inputs'!C37,IF(OR('Model inputs'!H43="",'Model inputs'!C37=""),"",'Model inputs'!H43<='Model inputs'!C37))="",FALSE,IF(ISERROR('Model inputs'!H43<='Model inputs'!C37),'Model inputs'!H43<='Model inputs'!C37,IF(OR('Model inputs'!H43="",'Model inputs'!C37=""),"",'Model inputs'!H43<='Model inputs'!C37))),('Model inputs'!C49-'Model inputs'!C46)/'Model inputs'!C37,0)="",0,IF(IF(IF(ISERROR('Model inputs'!H43<='Model inputs'!C37),'Model inputs'!H43<='Model inputs'!C37,IF(OR('Model inputs'!H43="",'Model inputs'!C37=""),"",'Model inputs'!H43<='Model inputs'!C37))="",FALSE,IF(ISERROR('Model inputs'!H43<='Model inputs'!C37),'Model inputs'!H43<='Model inputs'!C37,IF(OR('Model inputs'!H43="",'Model inputs'!C37=""),"",'Model inputs'!H43<='Model inputs'!C37))),('Model inputs'!C49-'Model inputs'!C46)/'Model inputs'!C37,0))+'Model inputs'!H24*'Model inputs'!C52 -> 22.533333 | I17: =IF(IF(IF(IF(ISERROR('Model inputs'!I43<='Model inputs'!C37),'Model inputs'!I43<='Model inputs'!C37,IF(OR('Model inputs'!I43="",'Model inputs'!C37=""),"",'Model inputs'!I43<='Model inputs'!C37))="",FALSE,IF(ISERROR('Model inputs'!I43<='Model inputs'!C37),'Model inputs'!I43<='Model inputs'!C37,IF(OR('Model inputs'!I43="",'Model inputs'!C37=""),"",'Model inputs'!I43<='Model inputs'!C37))),('Model inputs'!C49-'Model inputs'!C46)/'Model inputs'!C37,0)="",0,IF(IF(IF(ISERROR('Model inputs'!I43<='Model inputs'!C37),'Model inputs'!I43<='Model inputs'!C37,IF(OR('Model inputs'!I43="",'Model inputs'!C37=""),"",'Model inputs'!I43<='Model inputs'!C37))="",FALSE,IF(ISERROR('Model inputs'!I43<='Model inputs'!C37),'Model inputs'!I43<='Model inputs'!C37,IF(OR('Model inputs'!I43="",'Model inputs'!C37=""),"",'Model inputs'!I43<='Model inputs'!C37))),('Model inputs'!C49-'Model inputs'!C46)/'Model inputs'!C37,0))+'Model inputs'!I24*'Model inputs'!C52 -> 22.75 | J17: =IF(IF(IF(IF(ISERROR('Model inputs'!J43<='Model inputs'!C37),'Model inputs'!J43<='Model inputs'!C37,IF(OR('Model inputs'!J43="",'Model inputs'!C37=""),"",'Model inputs'!J43<='Model inputs'!C37))="",FALSE,IF(ISERROR('Model inputs'!J43<='Model inputs'!C37),'Model inputs'!J43<='Model inputs'!C37,IF(OR('Model inputs'!J43="",'Model inputs'!C37=""),"",'Model inputs'!J43<='Model inputs'!C37))),('Model inputs'!C49-'Model inputs'!C46)/'Model inputs'!C37,0)="",0,IF(IF(IF(ISERROR('Model inputs'!J43<='Model inputs'!C37),'Model inputs'!J43<='Model inputs'!C37,IF(OR('Model inputs'!J43="",'Model inputs'!C37=""),"",'Model inputs'!J43<='Model inputs'!C37))="",FALSE,IF(ISERROR('Model inputs'!J43<='Model inputs'!C37),'Model inputs'!J43<='Model inputs'!C37,IF(OR('Model inputs'!J43="",'Model inputs'!C37=""),"",'Model inputs'!J43<='Model inputs'!C37))),('Model inputs'!C49-'Model inputs'!C46)/'Model inputs'!C37,0))+'Model inputs'!J24*'Model inputs'!C52 -> 22.966667 | K17: =IF(IF(IF(IF(ISERROR('Model inputs'!K43<='Model inputs'!C37),'Model inputs'!K43<='Model inputs'!C37,IF(OR('Model inputs'!K43="",'Model inputs'!C37=""),"",'Model inputs'!K43<='Model inputs'!C37))="",FALSE,IF(ISERROR('Model inputs'!K43<='Model inputs'!C37),'Model inputs'!K43<='Model inputs'!C37,IF(OR('Model inputs'!K43="",'Model inputs'!C37=""),"",'Model inputs'!K43<='Model inputs'!C37))),('Model inputs'!C49-'Model inputs'!C46)/'Model inputs'!C37,0)="",0,IF(IF(IF(ISERROR('Model inputs'!K43<='Model inputs'!C37),'Model inputs'!K43<='Model inputs'!C37,IF(OR('Model inputs'!K43="",'Model inputs'!C37=""),"",'Model inputs'!K43<='Model inputs'!C37))="",FALSE,IF(ISERROR('Model inputs'!K43<='Model inputs'!C37),'Model inputs'!K43<='Model inputs'!C37,IF(OR('Model inputs'!K43="",'Model inputs'!C37=""),"",'Model inputs'!K43<='Model inputs'!C37))),('Model inputs'!C49-'Model inputs'!C46)/'Model inputs'!C37,0))+'Model inputs'!K24*'Model inputs'!C52 -> 23.183333 | L17: =IF(IF(IF(IF(ISERROR('Model inputs'!L43<='Model inputs'!C37),'Model inputs'!L43<='Model inputs'!C37,IF(OR('Model inputs'!L43="",'Model inputs'!C37=""),"",'Model inputs'!L43<='Model inputs'!C37))="",FALSE,IF(ISERROR('Model inputs'!L43<='Model inputs'!C37),'Model inputs'!L43<='Model inputs'!C37,IF(OR('Model inputs'!L43="",'Model inputs'!C37=""),"",'Model inputs'!L43<='Model inputs'!C37))),('Model inputs'!C49-'Model inputs'!C46)/'Model inputs'!C37,0)="",0,IF(IF(IF(ISERROR('Model inputs'!L43<='Model inputs'!C37),'Model inputs'!L43<='Model inputs'!C37,IF(OR('Model inputs'!L43="",'Model inputs'!C37=""),"",'Model inputs'!L43<='Model inputs'!C37))="",FALSE,IF(ISERROR('Model inputs'!L43<='Model inputs'!C37),'Model inputs'!L43<='Model inputs'!C37,IF(OR('Model inputs'!L43="",'Model inputs'!C37=""),"",'Model inputs'!L43<='Model inputs'!C37))),('Model inputs'!C49-'Model inputs'!C46)/'Model inputs'!C37,0))+'Model inputs'!L24*'Model inputs'!C52 -> 23.4 | M17: =IF(IF(IF(IF(ISERROR('Model inputs'!M43<='Model inputs'!C37),'Model inputs'!M43<='Model inputs'!C37,IF(OR('Model inputs'!M43="",'Model inputs'!C37=""),"",'Model inputs'!M43<='Model inputs'!C37))="",FALSE,IF(ISERROR('Model inputs'!M43<='Model inputs'!C37),'Model inputs'!M43<='Model inputs'!C37,IF(OR('Model inputs'!M43="",'Model inputs'!C37=""),"",'Model inputs'!M43<='Model inputs'!C37))),('Model inputs'!C49-'Model inputs'!C46)/'Model inputs'!C37,0)="",0,IF(IF(IF(ISERROR('Model inputs'!M43<='Model inputs'!C37),'Model inputs'!M43<='Model inputs'!C37,IF(OR('Model inputs'!M43="",'Model inputs'!C37=""),"",'Model inputs'!M43<='Model inputs'!C37))="",FALSE,IF(ISERROR('Model inputs'!M43<='Model inputs'!C37),'Model inputs'!M43<='Model inputs'!C37,IF(OR('Model inputs'!M43="",'Model inputs'!C37=""),"",'Model inputs'!M43<='Model inputs'!C37))),('Model inputs'!C49-'Model inputs'!C46)/'Model inputs'!C37,0))+'Model inputs'!M24*'Model inputs'!C52 -> 23.616667 | N17: =IF(IF(IF(IF(ISERROR('Model inputs'!N43<='Model inputs'!C37),'Model inputs'!N43<='Model inputs'!C37,IF(OR('Model inputs'!N43="",'Model inputs'!C37=""),"",'Model inputs'!N43<='Model inputs'!C37))="",FALSE,IF(ISERROR('Model inputs'!N43<='Model inputs'!C37),'Model inputs'!N43<='Model inputs'!C37,IF(OR('Model inputs'!N43="",'Model inputs'!C37=""),"",'Model inputs'!N43<='Model inputs'!C37))),('Model inputs'!C49-'Model inputs'!C46)/'Model inputs'!C37,0)="",0,IF(IF(IF(ISERROR('Model inputs'!N43<='Model inputs'!C37),'Model inputs'!N43<='Model inputs'!C37,IF(OR('Model inputs'!N43="",'Model inputs'!C37=""),"",'Model inputs'!N43<='Model inputs'!C37))="",FALSE,IF(ISERROR('Model inputs'!N43<='Model inputs'!C37),'Model inputs'!N43<='Model inputs'!C37,IF(OR('Model inputs'!N43="",'Model inputs'!C37=""),"",'Model inputs'!N43<='Model inputs'!C37))),('Model inputs'!C49-'Model inputs'!C46)/'Model inputs'!C37,0))+'Model inputs'!N24*'Model inputs'!C52 -> 23.833333 | O17: =IF(IF(IF(IF(ISERROR('Model inputs'!O43<='Model inputs'!C37),'Model inputs'!O43<='Model inputs'!C37,IF(OR('Model inputs'!O43="",'Model inputs'!C37=""),"",'Model inputs'!O43<='Model inputs'!C37))="",FALSE,IF(ISERROR('Model inputs'!O43<='Model inputs'!C37),'Model inputs'!O43<='Model inputs'!C37,IF(OR('Model inputs'!O43="",'Model inputs'!C37=""),"",'Model inputs'!O43<='Model inputs'!C37))),('Model inputs'!C49-'Model inputs'!C46)/'Model inputs'!C37,0)="",0,IF(IF(IF(ISERROR('Model inputs'!O43<='Model inputs'!C37),'Model inputs'!O43<='Model inputs'!C37,IF(OR('Model inputs'!O43="",'Model inputs'!C37=""),"",'Model inputs'!O43<='Model inputs'!C37))="",FALSE,IF(ISERROR('Model inputs'!O43<='Model inputs'!C37),'Model inputs'!O43<='Model inputs'!C37,IF(OR('Model inputs'!O43="",'Model inputs'!C37=""),"",'Model inputs'!O43<='Model inputs'!C37))),('Model inputs'!C49-'Model inputs'!C46)/'Model inputs'!C37,0))+'Model inputs'!O24*'Model inputs'!C52 -> 24.05 | X17: 0
