Workbook

Sheet TenantGuard cash forecast
A1: TenantGuard cash forecast
A2: TenantGuard — Cash · Main Scenario
A4: Variable / dimension | B4: 2026-10 | C4: 2026-11 | D4: 2026-12 | E4: 2027-01 | F4: 2027-02 | G4: 2027-03 | H4: 2027-04 | I4: 2027-05 | J4: 2027-06 | K4: 2027-07 | L4: 2027-08 | M4: 2027-09 | N4: 2027-10 | O4: 2027-11 | P4: 2027-12 | Q4: 2028-01 | R4: 2028-02 | S4: 2028-03 | T4: 2028-04 | U4: 2028-05 | V4: 2028-06 | W4: 2028-07 | X4: 2028-08 | Y4: 2028-09 | Z4: 2028-10 | AA4: 2028-11 | AB4: 2028-12 | AC4: 2029-01 | AD4: 2029-02 | AE4: 2029-03 | AF4: 2029-04 | AG4: 2029-05 | AH4: 2029-06 | AI4: 2029-07 | AJ4: 2029-08 | AK4: 2029-09
A5: TenantGuard revenue | B5: ='Model inputs'!D10*'Model inputs'!B7 -> 6500 | C5: ='Model inputs'!E10*'Model inputs'!B7 -> 13000 | D5: ='Model inputs'!F10*'Model inputs'!B7 -> 19500 | E5: ='Model inputs'!G10*'Model inputs'!B7 -> 26000 | F5: ='Model inputs'!H10*'Model inputs'!B7 -> 32500 | G5: ='Model inputs'!I10*'Model inputs'!B7 -> 39000 | H5: ='Model inputs'!J10*'Model inputs'!B7 -> 45500 | I5: ='Model inputs'!K10*'Model inputs'!B7 -> 52000 | J5: ='Model inputs'!L10*'Model inputs'!B7 -> 58500 | K5: ='Model inputs'!M10*'Model inputs'!B7 -> 65000 | L5: ='Model inputs'!N10*'Model inputs'!B7 -> 71500 | M5: ='Model inputs'!O10*'Model inputs'!B7 -> 78000 | N5: ='Model inputs'!P10*'Model inputs'!B7 -> 78000 | O5: ='Model inputs'!Q10*'Model inputs'!B7 -> 78000 | P5: ='Model inputs'!R10*'Model inputs'!B7 -> 78000 | Q5: ='Model inputs'!S10*'Model inputs'!B7 -> 78000 | R5: ='Model inputs'!T10*'Model inputs'!B7 -> 78000 | S5: ='Model inputs'!U10*'Model inputs'!B7 -> 78000 | T5: ='Model inputs'!V10*'Model inputs'!B7 -> 78000 | U5: ='Model inputs'!W10*'Model inputs'!B7 -> 78000 | V5: ='Model inputs'!X10*'Model inputs'!B7 -> 78000 | W5: ='Model inputs'!Y10*'Model inputs'!B7 -> 78000 | X5: ='Model inputs'!Z10*'Model inputs'!B7 -> 78000 | Y5: ='Model inputs'!AA10*'Model inputs'!B7 -> 78000 | Z5: ='Model inputs'!AB10*'Model inputs'!B7 -> 78000 | AA5: ='Model inputs'!AC10*'Model inputs'!B7 -> 78000 | AB5: ='Model inputs'!AD10*'Model inputs'!B7 -> 78000 | AC5: ='Model inputs'!AE10*'Model inputs'!B7 -> 78000 | AD5: ='Model inputs'!AF10*'Model inputs'!B7 -> 78000 | AE5: ='Model inputs'!AG10*'Model inputs'!B7 -> 78000 | AF5: ='Model inputs'!AH10*'Model inputs'!B7 -> 78000 | AG5: ='Model inputs'!AI10*'Model inputs'!B7 -> 78000 | AH5: ='Model inputs'!AJ10*'Model inputs'!B7 -> 78000 | AI5: ='Model inputs'!AK10*'Model inputs'!B7 -> 78000 | AJ5: ='Model inputs'!AL10*'Model inputs'!B7 -> 78000 | AK5: ='Model inputs'!AM10*'Model inputs'!B7 -> 78000
A6: Remediation compute COGS | B6: ='Model inputs'!D8*('Model inputs'!B18*'Model inputs'!B6+'Model inputs'!B9) -> 42.5 | C6: ='Model inputs'!E8*('Model inputs'!B18*'Model inputs'!B6+'Model inputs'!B9) -> 85 | D6: ='Model inputs'!F8*('Model inputs'!B18*'Model inputs'!B6+'Model inputs'!B9) -> 127.5 | E6: ='Model inputs'!G8*('Model inputs'!B18*'Model inputs'!B6+'Model inputs'!B9) -> 170 | F6: ='Model inputs'!H8*('Model inputs'!B18*'Model inputs'!B6+'Model inputs'!B9) -> 212.5 | G6: ='Model inputs'!I8*('Model inputs'!B18*'Model inputs'!B6+'Model inputs'!B9) -> 255 | H6: ='Model inputs'!J8*('Model inputs'!B18*'Model inputs'!B6+'Model inputs'!B9) -> 297.5 | I6: ='Model inputs'!K8*('Model inputs'!B18*'Model inputs'!B6+'Model inputs'!B9) -> 340 | J6: ='Model inputs'!L8*('Model inputs'!B18*'Model inputs'!B6+'Model inputs'!B9) -> 382.5 | K6: ='Model inputs'!M8*('Model inputs'!B18*'Model inputs'!B6+'Model inputs'!B9) -> 425 | L6: ='Model inputs'!N8*('Model inputs'!B18*'Model inputs'!B6+'Model inputs'!B9) -> 467.5 | M6: ='Model inputs'!O8*('Model inputs'!B18*'Model inputs'!B6+'Model inputs'!B9) -> 510 | N6: ='Model inputs'!P8*('Model inputs'!B18*'Model inputs'!B6+'Model inputs'!B9) -> 510 | O6: ='Model inputs'!Q8*('Model inputs'!B18*'Model inputs'!B6+'Model inputs'!B9) -> 510 | P6: ='Model inputs'!R8*('Model inputs'!B18*'Model inputs'!B6+'Model inputs'!B9) -> 510 | Q6: ='Model inputs'!S8*('Model inputs'!B18*'Model inputs'!B6+'Model inputs'!B9) -> 510 | R6: ='Model inputs'!T8*('Model inputs'!B18*'Model inputs'!B6+'Model inputs'!B9) -> 510 | S6: ='Model inputs'!U8*('Model inputs'!B18*'Model inputs'!B6+'Model inputs'!B9) -> 510 | T6: ='Model inputs'!V8*('Model inputs'!B18*'Model inputs'!B6+'Model inputs'!B9) -> 510 | U6: ='Model inputs'!W8*('Model inputs'!B18*'Model inputs'!B6+'Model inputs'!B9) -> 510 | V6: ='Model inputs'!X8*('Model inputs'!B18*'Model inputs'!B6+'Model inputs'!B9) -> 510 | W6: ='Model inputs'!Y8*('Model inputs'!B18*'Model inputs'!B6+'Model inputs'!B9) -> 510 | X6: ='Model inputs'!Z8*('Model inputs'!B18*'Model inputs'!B6+'Model inputs'!B9) -> 510 | Y6: ='Model inputs'!AA8*('Model inputs'!B18*'Model inputs'!B6+'Model inputs'!B9) -> 510 | Z6: ='Model inputs'!AB8*('Model inputs'!B18*'Model inputs'!B6+'Model inputs'!B9) -> 510 | AA6: ='Model inputs'!AC8*('Model inputs'!B18*'Model inputs'!B6+'Model inputs'!B9) -> 510 | AB6: ='Model inputs'!AD8*('Model inputs'!B18*'Model inputs'!B6+'Model inputs'!B9) -> 510 | AC6: ='Model inputs'!AE8*('Model inputs'!B18*'Model inputs'!B6+'Model inputs'!B9) -> 510 | AD6: ='Model inputs'!AF8*('Model inputs'!B18*'Model inputs'!B6+'Model inputs'!B9) -> 510 | AE6: ='Model inputs'!AG8*('Model inputs'!B18*'Model inputs'!B6+'Model inputs'!B9) -> 510 | AF6: ='Model inputs'!AH8*('Model inputs'!B18*'Model inputs'!B6+'Model inputs'!B9) -> 510 | AG6: ='Model inputs'!AI8*('Model inputs'!B18*'Model inputs'!B6+'Model inputs'!B9) -> 510 | AH6: ='Model inputs'!AJ8*('Model inputs'!B18*'Model inputs'!B6+'Model inputs'!B9) -> 510 | AI6: ='Model inputs'!AK8*('Model inputs'!B18*'Model inputs'!B6+'Model inputs'!B9) -> 510 | AJ6: ='Model inputs'!AL8*('Model inputs'!B18*'Model inputs'!B6+'Model inputs'!B9) -> 510 | AK6: ='Model inputs'!AM8*('Model inputs'!B18*'Model inputs'!B6+'Model inputs'!B9) -> 510
A7: TenantGuard fixed operating spend | B7: =IF('Model inputs'!B11="","",'Model inputs'!B11) -> 50000 | C7: =IF('Model inputs'!B11="","",'Model inputs'!B11) -> 50000 | D7: =IF('Model inputs'!B11="","",'Model inputs'!B11) -> 50000 | E7: =IF('Model inputs'!B11="","",'Model inputs'!B11) -> 50000 | F7: =IF('Model inputs'!B11="","",'Model inputs'!B11) -> 50000 | G7: =IF('Model inputs'!B11="","",'Model inputs'!B11) -> 50000 | H7: =IF('Model inputs'!B11="","",'Model inputs'!B11) -> 50000 | I7: =IF('Model inputs'!B11="","",'Model inputs'!B11) -> 50000 | J7: =IF('Model inputs'!B11="","",'Model inputs'!B11) -> 50000 | K7: =IF('Model inputs'!B11="","",'Model inputs'!B11) -> 50000 | L7: =IF('Model inputs'!B11="","",'Model inputs'!B11) -> 50000 | M7: =IF('Model inputs'!B11="","",'Model inputs'!B11) -> 50000 | N7: =IF('Model inputs'!B11="","",'Model inputs'!B11) -> 50000 | O7: =IF('Model inputs'!B11="","",'Model inputs'!B11) -> 50000 | P7: =IF('Model inputs'!B11="","",'Model inputs'!B11) -> 50000 | Q7: =IF('Model inputs'!B11="","",'Model inputs'!B11) -> 50000 | R7: =IF('Model inputs'!B11="","",'Model inputs'!B11) -> 50000 | S7: =IF('Model inputs'!B11="","",'Model inputs'!B11) -> 50000 | T7: =IF('Model inputs'!B11="","",'Model inputs'!B11) -> 50000 | U7: =IF('Model inputs'!B11="","",'Model inputs'!B11) -> 50000 | V7: =IF('Model inputs'!B11="","",'Model inputs'!B11) -> 50000 | W7: =IF('Model inputs'!B11="","",'Model inputs'!B11) -> 50000 | X7: =IF('Model inputs'!B11="","",'Model inputs'!B11) -> 50000 | Y7: =IF('Model inputs'!B11="","",'Model inputs'!B11) -> 50000 | Z7: =IF('Model inputs'!B11="","",'Model inputs'!B11) -> 50000 | AA7: =IF('Model inputs'!B11="","",'Model inputs'!B11) -> 50000 | AB7: =IF('Model inputs'!B11="","",'Model inputs'!B11) -> 50000 | AC7: =IF('Model inputs'!B11="","",'Model inputs'!B11) -> 50000 | AD7: =IF('Model inputs'!B11="","",'Model inputs'!B11) -> 50000 | AE7: =IF('Model inputs'!B11="","",'Model inputs'!B11) -> 50000 | AF7: =IF('Model inputs'!B11="","",'Model inputs'!B11) -> 50000 | AG7: =IF('Model inputs'!B11="","",'Model inputs'!B11) -> 50000 | AH7: =IF('Model inputs'!B11="","",'Model inputs'!B11) -> 50000 | AI7: =IF('Model inputs'!B11="","",'Model inputs'!B11) -> 50000 | AJ7: =IF('Model inputs'!B11="","",'Model inputs'!B11) -> 50000 | AK7: =IF('Model inputs'!B11="","",'Model inputs'!B11) -> 50000
A8: TenantGuard net cash flow | B8: ='TenantGuard cash forecast'!B5-'TenantGuard cash forecast'!B6-'TenantGuard cash forecast'!B7 -> -43542.5 | C8: ='TenantGuard cash forecast'!C5-'TenantGuard cash forecast'!C6-'TenantGuard cash forecast'!C7 -> -37085 | D8: ='TenantGuard cash forecast'!D5-'TenantGuard cash forecast'!D6-'TenantGuard cash forecast'!D7 -> -30627.5 | E8: ='TenantGuard cash forecast'!E5-'TenantGuard cash forecast'!E6-'TenantGuard cash forecast'!E7 -> -24170 | F8: ='TenantGuard cash forecast'!F5-'TenantGuard cash forecast'!F6-'TenantGuard cash forecast'!F7 -> -17712.5 | G8: ='TenantGuard cash forecast'!G5-'TenantGuard cash forecast'!G6-'TenantGuard cash forecast'!G7 -> -11255 | H8: ='TenantGuard cash forecast'!H5-'TenantGuard cash forecast'!H6-'TenantGuard cash forecast'!H7 -> -4797.5 | I8: ='TenantGuard cash forecast'!I5-'TenantGuard cash forecast'!I6-'TenantGuard cash forecast'!I7 -> 1660 | ... AK8: ='TenantGuard cash forecast'!AK5-'TenantGuard cash forecast'!AK6-'TenantGuard cash forecast'!AK7 -> 27490
A9: TenantGuard ending cash | B9: =IF(IF(DATE(2026,10,1)=DATE(2026,10,1),IF('Model inputs'!B12="","",'Model inputs'!B12),IF('Model inputs'!C14="","",'Model inputs'!C14))="",0,IF(DATE(2026,10,1)=DATE(2026,10,1),IF('Model inputs'!B12="","",'Model inputs'!B12),IF('Model inputs'!C14="","",'Model inputs'!C14)))+'TenantGuard cash forecast'!B8 -> 856457.5 | C9: =IF(IF(DATE(2026,11,1)=DATE(2026,10,1),IF('Model inputs'!B12="","",'Model inputs'!B12),IF('TenantGuard cash forecast'!B9="","",'TenantGuard cash forecast'!B9))="",0,IF(DATE(2026,11,1)=DATE(2026,10,1),IF('Model inputs'!B12="","",'Model inputs'!B12),IF('TenantGuard cash forecast'!B9="","",'TenantGuard cash forecast'!B9)))+'TenantGuard cash forecast'!C8 -> 819372.5 | D9: =IF(IF(DATE(2026,12,1)=DATE(2026,10,1),IF('Model inputs'!B12="","",'Model inputs'!B12),IF('TenantGuard cash forecast'!C9="","",'TenantGuard cash forecast'!C9))="",0,IF(DATE(2026,12,1)=DATE(2026,10,1),IF('Model inputs'!B12="","",'Model inputs'!B12),IF('TenantGuard cash forecast'!C9="","",'TenantGuard cash forecast'!C9)))+'TenantGuard cash forecast'!D8 -> 788745 | E9: =IF(IF(DATE(2027,1,1)=DATE(2026,10,1),IF('Model inputs'!B12="","",'Model inputs'!B12),IF('TenantGuard cash forecast'!D9="","",'TenantGuard cash forecast'!D9))="",0,IF(DATE(2027,1,1)=DATE(2026,10,1),IF('Model inputs'!B12="","",'Model inputs'!B12),IF('TenantGuard cash forecast'!D9="","",'TenantGuard cash forecast'!D9)))+'TenantGuard cash forecast'!E8 -> 764575 | F9: =IF(IF(DATE(2027,2,1)=DATE(2026,10,1),IF('Model inputs'!B12="","",'Model inputs'!B12),IF('TenantGuard cash forecast'!E9="","",'TenantGuard cash forecast'!E9))="",0,IF(DATE(2027,2,1)=DATE(2026,10,1),IF('Model inputs'!B12="","",'Model inputs'!B12),IF('TenantGuard cash forecast'!E9="","",'TenantGuard cash forecast'!E9)))+'TenantGuard cash forecast'!F8 -> 746862.5 | G9: =IF(IF(DATE(2027,3,1)=DATE(2026,10,1),IF('Model inputs'!B12="","",'Model inputs'!B12),IF('TenantGuard cash forecast'!F9="","",'TenantGuard cash forecast'!F9))="",0,IF(DATE(2027,3,1)=DATE(2026,10,1),IF('Model inputs'!B12="","",'Model inputs'!B12),IF('TenantGuard cash forecast'!F9="","",'TenantGuard cash forecast'!F9)))+'TenantGuard cash forecast'!G8 -> 735607.5 | H9: =IF(IF(DATE(2027,4,1)=DATE(2026,10,1),IF('Model inputs'!B12="","",'Model inputs'!B12),IF('TenantGuard cash forecast'!G9="","",'TenantGuard cash forecast'!G9))="",0,IF(DATE(2027,4,1)=DATE(2026,10,1),IF('Model inputs'!B12="","",'Model inputs'!B12),IF('TenantGuard cash forecast'!G9="","",'TenantGuard cash forecast'!G9)))+'TenantGuard cash forecast'!H8 -> 730810 | I9: =IF(IF(DATE(2027,5,1)=DATE(2026,10,1),IF('Model inputs'!B12="","",'Model inputs'!B12),IF('TenantGuard cash forecast'!H9="","",'TenantGuard cash forecast'!H9))="",0,IF(DATE(2027,5,1)=DATE(2026,10,1),IF('Model inputs'!B12="","",'Model inputs'!B12),IF('TenantGuard cash forecast'!H9="","",'TenantGuard cash forecast'!H9)))+'TenantGuard cash forecast'!I8 -> 732470 | J9: =IF(IF(DATE(2027,6,1)=DATE(2026,10,1),IF('Model inputs'!B12="","",'Model inputs'!B12),IF('TenantGuard cash forecast'!I9="","",'TenantGuard cash forecast'!I9))="",0,IF(DATE(2027,6,1)=DATE(2026,10,1),IF('Model inputs'!B12="","",'Model inputs'!B12),IF('TenantGuard cash forecast'!I9="","",'TenantGuard cash forecast'!I9)))+'TenantGuard cash forecast'!J8 -> 740587.5 | K9: =IF(IF(DATE(2027,7,1)=DATE(2026,10,1),IF('Model inputs'!B12="","",'Model inputs'!B12),IF('TenantGuard cash forecast'!J9="","",'TenantGuard cash forecast'!J9))="",0,IF(DATE(2027,7,1)=DATE(2026,10,1),IF('Model inputs'!B12="","",'Model inputs'!B12),IF('TenantGuard cash forecast'!J9="","",'TenantGuard cash forecast'!J9)))+'TenantGuard cash forecast'!K8 -> 755162.5 | L9: =IF(IF(DATE(2027,8,1)=DATE(2026,10,1),IF('Model inputs'!B12="","",'Model inputs'!B12),IF('TenantGuard cash forecast'!K9="","",'TenantGuard cash forecast'!K9))="",0,IF(DATE(2027,8,1)=DATE(2026,10,1),IF('Model inputs'!B12="","",'Model inputs'!B12),IF('TenantGuard cash forecast'!K9="","",'TenantGuard cash forecast'!K9)))+'TenantGuard cash forecast'!L8 -> 776195 | M9: =IF(IF(DATE(2027,9,1)=DATE(2026,10,1),IF('Model inputs'!B12="","",'Model inputs'!B12),IF('TenantGuard cash forecast'!L9="","",'TenantGuard cash forecast'!L9))="",0,IF(DATE(2027,9,1)=DATE(2026,10,1),IF('Model inputs'!B12="","",'Model inputs'!B12),IF('TenantGuard cash forecast'!L9="","",'TenantGuard cash forecast'!L9)))+'TenantGuard cash forecast'!M8 -> 803685 | N9: =IF(IF(DATE(2027,10,1)=DATE(2026,10,1),IF('Model inputs'!B12="","",'Model inputs'!B12),IF('TenantGuard cash forecast'!M9="","",'TenantGuard cash forecast'!M9))="",0,IF(DATE(2027,10,1)=DATE(2026,10,1),IF('Model inputs'!B12="","",'Model inputs'!B12),IF('TenantGuard cash forecast'!M9="","",'TenantGuard cash forecast'!M9)))+'TenantGuard cash forecast'!N8 -> 831175 | O9: =IF(IF(DATE(2027,11,1)=DATE(2026,10,1),IF('Model inputs'!B12="","",'Model inputs'!B12),IF('TenantGuard cash forecast'!N9="","",'TenantGuard cash forecast'!N9))="",0,IF(DATE(2027,11,1)=DATE(2026,10,1),IF('Model inputs'!B12="","",'Model inputs'!B12),IF('TenantGuard cash forecast'!N9="","",'TenantGuard cash forecast'!N9)))+'TenantGuard cash forecast'!O8 -> 858665 | P9: =IF(IF(DATE(2027,12,1)=DATE(2026,10,1),IF('Model inputs'!B12="","",'Model inputs'!B12),IF('TenantGuard cash forecast'!O9="","",'TenantGuard cash forecast'!O9))="",0,IF(DATE(2027,12,1)=DATE(2026,10,1),IF('Model inputs'!B12="","",'Model inputs'!B12),IF('TenantGuard cash forecast'!O9="","",'TenantGuard cash forecast'!O9)))+'TenantGuard cash forecast'!P8 -> 886155 | Q9: =IF(IF(DATE(2028,1,1)=DATE(2026,10,1),IF('Model inputs'!B12="","",'Model inputs'!B12),IF('TenantGuard cash forecast'!P9="","",'TenantGuard cash forecast'!P9))="",0,IF(DATE(2028,1,1)=DATE(2026,10,1),IF('Model inputs'!B12="","",'Model inputs'!B12),IF('TenantGuard cash forecast'!P9="","",'TenantGuard cash forecast'!P9)))+'TenantGuard cash forecast'!Q8 -> 913645 | R9: =IF(IF(DATE(2028,2,1)=DATE(2026,10,1),IF('Model inputs'!B12="","",'Model inputs'!B12),IF('TenantGuard cash forecast'!Q9="","",'TenantGuard cash forecast'!Q9))="",0,IF(DATE(2028,2,1)=DATE(2026,10,1),IF('Model inputs'!B12="","",'Model inputs'!B12),IF('TenantGuard cash forecast'!Q9="","",'TenantGuard cash forecast'!Q9)))+'TenantGuard cash forecast'!R8 -> 941135 | S9: =IF(IF(DATE(2028,3,1)=DATE(2026,10,1),IF('Model inputs'!B12="","",'Model inputs'!B12),IF('TenantGuard cash forecast'!R9="","",'TenantGuard cash forecast'!R9))="",0,IF(DATE(2028,3,1)=DATE(2026,10,1),IF('Model inputs'!B12="","",'Model inputs'!B12),IF('TenantGuard cash forecast'!R9="","",'TenantGuard cash forecast'!R9)))+'TenantGuard cash forecast'!S8 -> 968625 | T9: =IF(IF(DATE(2028,4,1)=DATE(2026,10,1),IF('Model inputs'!B12="","",'Model inputs'!B12),IF('TenantGuard cash forecast'!S9="","",'TenantGuard cash forecast'!S9))="",0,IF(DATE(2028,4,1)=DATE(2026,10,1),IF('Model inputs'!B12="","",'Model inputs'!B12),IF('TenantGuard cash forecast'!S9="","",'TenantGuard cash forecast'!S9)))+'TenantGuard cash forecast'!T8 -> 996115 | U9: =IF(IF(DATE(2028,5,1)=DATE(2026,10,1),IF('Model inputs'!B12="","",'Model inputs'!B12),IF('TenantGuard cash forecast'!T9="","",'TenantGuard cash forecast'!T9))="",0,IF(DATE(2028,5,1)=DATE(2026,10,1),IF('Model inputs'!B12="","",'Model inputs'!B12),IF('TenantGuard cash forecast'!T9="","",'TenantGuard cash forecast'!T9)))+'TenantGuard cash forecast'!U8 -> 1023605 | V9: =IF(IF(DATE(2028,6,1)=DATE(2026,10,1),IF('Model inputs'!B12="","",'Model inputs'!B12),IF('TenantGuard cash forecast'!U9="","",'TenantGuard cash forecast'!U9))="",0,IF(DATE(2028,6,1)=DATE(2026,10,1),IF('Model inputs'!B12="","",'Model inputs'!B12),IF('TenantGuard cash forecast'!U9="","",'TenantGuard cash forecast'!U9)))+'TenantGuard cash forecast'!V8 -> 1051095 | W9: =IF(IF(DATE(2028,7,1)=DATE(2026,10,1),IF('Model inputs'!B12="","",'Model inputs'!B12),IF('TenantGuard cash forecast'!V9="","",'TenantGuard cash forecast'!V9))="",0,IF(DATE(2028,7,1)=DATE(2026,10,1),IF('Model inputs'!B12="","",'Model inputs'!B12),IF('TenantGuard cash forecast'!V9="","",'TenantGuard cash forecast'!V9)))+'TenantGuard cash forecast'!W8 -> 1078585 | X9: =IF(IF(DATE(2028,8,1)=DATE(2026,10,1),IF('Model inputs'!B12="","",'Model inputs'!B12),IF('TenantGuard cash forecast'!W9="","",'TenantGuard cash forecast'!W9))="",0,IF(DATE(2028,8,1)=DATE(2026,10,1),IF('Model inputs'!B12="","",'Model inputs'!B12),IF('TenantGuard cash forecast'!W9="","",'TenantGuard cash forecast'!W9)))+'TenantGuard cash forecast'!X8 -> 1106075 | Y9: =IF(IF(DATE(2028,9,1)=DATE(2026,10,1),IF('Model inputs'!B12="","",'Model inputs'!B12),IF('TenantGuard cash forecast'!X9="","",'TenantGuard cash forecast'!X9))="",0,IF(DATE(2028,9,1)=DATE(2026,10,1),IF('Model inputs'!B12="","",'Model inputs'!B12),IF('TenantGuard cash forecast'!X9="","",'TenantGuard cash forecast'!X9)))+'TenantGuard cash forecast'!Y8 -> 1133565 | Z9: =IF(IF(DATE(2028,10,1)=DATE(2026,10,1),IF('Model inputs'!B12="","",'Model inputs'!B12),IF('TenantGuard cash forecast'!Y9="","",'TenantGuard cash forecast'!Y9))="",0,IF(DATE(2028,10,1)=DATE(2026,10,1),IF('Model inputs'!B12="","",'Model inputs'!B12),IF('TenantGuard cash forecast'!Y9="","",'TenantGuard cash forecast'!Y9)))+'TenantGuard cash forecast'!Z8 -> 1161055 | AA9: =IF(IF(DATE(2028,11,1)=DATE(2026,10,1),IF('Model inputs'!B12="","",'Model inputs'!B12),IF('TenantGuard cash forecast'!Z9="","",'TenantGuard cash forecast'!Z9))="",0,IF(DATE(2028,11,1)=DATE(2026,10,1),IF('Model inputs'!B12="","",'Model inputs'!B12),IF('TenantGuard cash forecast'!Z9="","",'TenantGuard cash forecast'!Z9)))+'TenantGuard cash forecast'!AA8 -> 1188545 | AB9: =IF(IF(DATE(2028,12,1)=DATE(2026,10,1),IF('Model inputs'!B12="","",'Model inputs'!B12),IF('TenantGuard cash forecast'!AA9="","",'TenantGuard cash forecast'!AA9))="",0,IF(DATE(2028,12,1)=DATE(2026,10,1),IF('Model inputs'!B12="","",'Model inputs'!B12),IF('TenantGuard cash forecast'!AA9="","",'TenantGuard cash forecast'!AA9)))+'TenantGuard cash forecast'!AB8 -> 1216035 | AC9: =IF(IF(DATE(2029,1,1)=DATE(2026,10,1),IF('Model inputs'!B12="","",'Model inputs'!B12),IF('TenantGuard cash forecast'!AB9="","",'TenantGuard cash forecast'!AB9))="",0,IF(DATE(2029,1,1)=DATE(2026,10,1),IF('Model inputs'!B12="","",'Model inputs'!B12),IF('TenantGuard cash forecast'!AB9="","",'TenantGuard cash forecast'!AB9)))+'TenantGuard cash forecast'!AC8 -> 1243525 | AD9: =IF(IF(DATE(2029,2,1)=DATE(2026,10,1),IF('Model inputs'!B12="","",'Model inputs'!B12),IF('TenantGuard cash forecast'!AC9="","",'TenantGuard cash forecast'!AC9))="",0,IF(DATE(2029,2,1)=DATE(2026,10,1),IF('Model inputs'!B12="","",'Model inputs'!B12),IF('TenantGuard cash forecast'!AC9="","",'TenantGuard cash forecast'!AC9)))+'TenantGuard cash forecast'!AD8 -> 1271015 | AE9: =IF(IF(DATE(2029,3,1)=DATE(2026,10,1),IF('Model inputs'!B12="","",'Model inputs'!B12),IF('TenantGuard cash forecast'!AD9="","",'TenantGuard cash forecast'!AD9))="",0,IF(DATE(2029,3,1)=DATE(2026,10,1),IF('Model inputs'!B12="","",'Model inputs'!B12),IF('TenantGuard cash forecast'!AD9="","",'TenantGuard cash forecast'!AD9)))+'TenantGuard cash forecast'!AE8 -> 1298505 | AF9: =IF(IF(DATE(2029,4,1)=DATE(2026,10,1),IF('Model inputs'!B12="","",'Model inputs'!B12),IF('TenantGuard cash forecast'!AE9="","",'TenantGuard cash forecast'!AE9))="",0,IF(DATE(2029,4,1)=DATE(2026,10,1),IF('Model inputs'!B12="","",'Model inputs'!B12),IF('TenantGuard cash forecast'!AE9="","",'TenantGuard cash forecast'!AE9)))+'TenantGuard cash forecast'!AF8 -> 1325995 | AG9: =IF(IF(DATE(2029,5,1)=DATE(2026,10,1),IF('Model inputs'!B12="","",'Model inputs'!B12),IF('TenantGuard cash forecast'!AF9="","",'TenantGuard cash forecast'!AF9))="",0,IF(DATE(2029,5,1)=DATE(2026,10,1),IF('Model inputs'!B12="","",'Model inputs'!B12),IF('TenantGuard cash forecast'!AF9="","",'TenantGuard cash forecast'!AF9)))+'TenantGuard cash forecast'!AG8 -> 1353485 | AH9: =IF(IF(DATE(2029,6,1)=DATE(2026,10,1),IF('Model inputs'!B12="","",'Model inputs'!B12),IF('TenantGuard cash forecast'!AG9="","",'TenantGuard cash forecast'!AG9))="",0,IF(DATE(2029,6,1)=DATE(2026,10,1),IF('Model inputs'!B12="","",'Model inputs'!B12),IF('TenantGuard cash forecast'!AG9="","",'TenantGuard cash forecast'!AG9)))+'TenantGuard cash forecast'!AH8 -> 1380975 | AI9: =IF(IF(DATE(2029,7,1)=DATE(2026,10,1),IF('Model inputs'!B12="","",'Model inputs'!B12),IF('TenantGuard cash forecast'!AH9="","",'TenantGuard cash forecast'!AH9))="",0,IF(DATE(2029,7,1)=DATE(2026,10,1),IF('Model inputs'!B12="","",'Model inputs'!B12),IF('TenantGuard cash forecast'!AH9="","",'TenantGuard cash forecast'!AH9)))+'TenantGuard cash forecast'!AI8 -> 1408465 | AJ9: =IF(IF(DATE(2029,8,1)=DATE(2026,10,1),IF('Model inputs'!B12="","",'Model inputs'!B12),IF('TenantGuard cash forecast'!AI9="","",'TenantGuard cash forecast'!AI9))="",0,IF(DATE(2029,8,1)=DATE(2026,10,1),IF('Model inputs'!B12="","",'Model inputs'!B12),IF('TenantGuard cash forecast'!AI9="","",'TenantGuard cash forecast'!AI9)))+'TenantGuard cash forecast'!AJ8 -> 1435955 | AK9: =IF(IF(DATE(2029,9,1)=DATE(2026,10,1),IF('Model inputs'!B12="","",'Model inputs'!B12),IF('TenantGuard cash forecast'!AJ9="","",'TenantGuard cash forecast'!AJ9))="",0,IF(DATE(2029,9,1)=DATE(2026,10,1),IF('Model inputs'!B12="","",'Model inputs'!B12),IF('TenantGuard cash forecast'!AJ9="","",'TenantGuard cash forecast'!AJ9)))+'TenantGuard cash forecast'!AK8 -> 1463445

Sheet Model inputs
A1: Model inputs
A2: Integration values are aggregated snapshots; raw source records are not included.
A4: Variables
A5: Variable / segment | B5: Value | C5: 2026-09 | D5: 2026-10 | E5: 2026-11 | F5: 2026-12 | G5: 2027-01 | H5: 2027-02 | I5: 2027-03 | J5: 2027-04 | K5: 2027-05 | L5: 2027-06 | M5: 2027-07 | N5: 2027-08 | O5: 2027-09 | P5: 2027-10 | Q5: 2027-11 | R5: 2027-12 | S5: 2028-01 | T5: 2028-02 | U5: 2028-03 | V5: 2028-04 | W5: 2028-05 | X5: 2028-06 | Y5: 2028-07 | Z5: 2028-08 | AA5: 2028-09 | AB5: 2028-10 | AC5: 2028-11 | AD5: 2028-12 | AE5: 2029-01 | AF5: 2029-02 | AG5: 2029-03 | AH5: 2029-04 | AI5: 2029-05 | AJ5: 2029-06 | AK5: 2029-07 | AL5: 2029-08 | AM5: 2029-09 | AN5: 2026-01 | AO5: 2026-02 | AP5: 2026-03 | AQ5: 2026-04 | AR5: 2026-05 | AS5: 2026-06 | AT5: 2026-07 | AU5: 2026-08
A6: Attempts per completed fix | B6: =2.5 -> 2.5
A7: Blended monthly ARPA | B7: =650 -> 650
A8: Completed remediations | C8: 0 | D8: ='Model inputs'!D10*'Model inputs'!B20 -> 1000 | E8: ='Model inputs'!E10*'Model inputs'!B20 -> 2000 | F8: ='Model inputs'!F10*'Model inputs'!B20 -> 3000 | G8: ='Model inputs'!G10*'Model inputs'!B20 -> 4000 | H8: ='Model inputs'!H10*'Model inputs'!B20 -> 5000 | I8: ='Model inputs'!I10*'Model inputs'!B20 -> 6000 | J8: ='Model inputs'!J10*'Model inputs'!B20 -> 7000 | K8: ='Model inputs'!K10*'Model inputs'!B20 -> 8000 | L8: ='Model inputs'!L10*'Model inputs'!B20 -> 9000 | M8: ='Model inputs'!M10*'Model inputs'!B20 -> 10000 | N8: ='Model inputs'!N10*'Model inputs'!B20 -> 11000 | O8: ='Model inputs'!O10*'Model inputs'!B20 -> 12000 | P8: ='Model inputs'!P10*'Model inputs'!B20 -> 12000 | Q8: ='Model inputs'!Q10*'Model inputs'!B20 -> 12000 | R8: ='Model inputs'!R10*'Model inputs'!B20 -> 12000 | S8: ='Model inputs'!S10*'Model inputs'!B20 -> 12000 | T8: ='Model inputs'!T10*'Model inputs'!B20 -> 12000 | U8: ='Model inputs'!U10*'Model inputs'!B20 -> 12000 | V8: ='Model inputs'!V10*'Model inputs'!B20 -> 12000 | W8: ='Model inputs'!W10*'Model inputs'!B20 -> 12000 | X8: ='Model inputs'!X10*'Model inputs'!B20 -> 12000 | Y8: ='Model inputs'!Y10*'Model inputs'!B20 -> 12000 | Z8: ='Model inputs'!Z10*'Model inputs'!B20 -> 12000 | AA8: ='Model inputs'!AA10*'Model inputs'!B20 -> 12000 | AB8: ='Model inputs'!AB10*'Model inputs'!B20 -> 12000 | AC8: ='Model inputs'!AC10*'Model inputs'!B20 -> 12000 | AD8: ='Model inputs'!AD10*'Model inputs'!B20 -> 12000 | AE8: ='Model inputs'!AE10*'Model inputs'!B20 -> 12000 | AF8: ='Model inputs'!AF10*'Model inputs'!B20 -> 12000 | AG8: ='Model inputs'!AG10*'Model inputs'!B20 -> 12000 | AH8: ='Model inputs'!AH10*'Model inputs'!B20 -> 12000 | AI8: ='Model inputs'!AI10*'Model inputs'!B20 -> 12000 | AJ8: ='Model inputs'!AJ10*'Model inputs'!B20 -> 12000 | AK8: ='Model inputs'!AK10*'Model inputs'!B20 -> 12000 | AL8: ='Model inputs'!AL10*'Model inputs'!B20 -> 12000 | AM8: ='Model inputs'!AM10*'Model inputs'!B20 -> 12000
A9: Compute cost per completed fix | B9: =0.03 -> 0.03
A10: Ending customers | C10: 0 | D10: ='Model inputs'!D22+'Model inputs'!D21-'Model inputs'!D19 -> 10 | E10: ='Model inputs'!E22+'Model inputs'!E21-'Model inputs'!E19 -> 20 | F10: ='Model inputs'!F22+'Model inputs'!F21-'Model inputs'!F19 -> 30 | G10: ='Model inputs'!G22+'Model inputs'!G21-'Model inputs'!G19 -> 40 | H10: ='Model inputs'!H22+'Model inputs'!H21-'Model inputs'!H19 -> 50 | I10: ='Model inputs'!I22+'Model inputs'!I21-'Model inputs'!I19 -> 60 | J10: ='Model inputs'!J22+'Model inputs'!J21-'Model inputs'!J19 -> 70 | K10: ='Model inputs'!K22+'Model inputs'!K21-'Model inputs'!K19 -> 80 | ... AM10: ='Model inputs'!AM22+'Model inputs'!AM21-'Model inputs'!AM19 -> 120
A11: Fixed monthly operating spend | B11: =50000 -> 50000
A12: Launch cash | B12: =900000 -> 900000
A13: Remediation compute COGS | C13: 0 | D13: ='Model inputs'!D8*('Model inputs'!B18*'Model inputs'!B6+'Model inputs'!B9) -> 42.5 | E13: ='Model inputs'!E8*('Model inputs'!B18*'Model inputs'!B6+'Model inputs'!B9) -> 85 | F13: ='Model inputs'!F8*('Model inputs'!B18*'Model inputs'!B6+'Model inputs'!B9) -> 127.5 | G13: ='Model inputs'!G8*('Model inputs'!B18*'Model inputs'!B6+'Model inputs'!B9) -> 170 | H13: ='Model inputs'!H8*('Model inputs'!B18*'Model inputs'!B6+'Model inputs'!B9) -> 212.5 | I13: ='Model inputs'!I8*('Model inputs'!B18*'Model inputs'!B6+'Model inputs'!B9) -> 255 | J13: ='Model inputs'!J8*('Model inputs'!B18*'Model inputs'!B6+'Model inputs'!B9) -> 297.5 | K13: ='Model inputs'!K8*('Model inputs'!B18*'Model inputs'!B6+'Model inputs'!B9) -> 340 | L13: ='Model inputs'!L8*('Model inputs'!B18*'Model inputs'!B6+'Model inputs'!B9) -> 382.5 | M13: ='Model inputs'!M8*('Model inputs'!B18*'Model inputs'!B6+'Model inputs'!B9) -> 425 | N13: ='Model inputs'!N8*('Model inputs'!B18*'Model inputs'!B6+'Model inputs'!B9) -> 467.5 | O13: ='Model inputs'!O8*('Model inputs'!B18*'Model inputs'!B6+'Model inputs'!B9) -> 510 | P13: ='Model inputs'!P8*('Model inputs'!B18*'Model inputs'!B6+'Model inputs'!B9) -> 510 | Q13: ='Model inputs'!Q8*('Model inputs'!B18*'Model inputs'!B6+'Model inputs'!B9) -> 510 | R13: ='Model inputs'!R8*('Model inputs'!B18*'Model inputs'!B6+'Model inputs'!B9) -> 510 | S13: ='Model inputs'!S8*('Model inputs'!B18*'Model inputs'!B6+'Model inputs'!B9) -> 510 | T13: ='Model inputs'!T8*('Model inputs'!B18*'Model inputs'!B6+'Model inputs'!B9) -> 510 | U13: ='Model inputs'!U8*('Model inputs'!B18*'Model inputs'!B6+'Model inputs'!B9) -> 510 | V13: ='Model inputs'!V8*('Model inputs'!B18*'Model inputs'!B6+'Model inputs'!B9) -> 510 | W13: ='Model inputs'!W8*('Model inputs'!B18*'Model inputs'!B6+'Model inputs'!B9) -> 510 | X13: ='Model inputs'!X8*('Model inputs'!B18*'Model inputs'!B6+'Model inputs'!B9) -> 510 | Y13: ='Model inputs'!Y8*('Model inputs'!B18*'Model inputs'!B6+'Model inputs'!B9) -> 510 | Z13: ='Model inputs'!Z8*('Model inputs'!B18*'Model inputs'!B6+'Model inputs'!B9) -> 510 | AA13: ='Model inputs'!AA8*('Model inputs'!B18*'Model inputs'!B6+'Model inputs'!B9) -> 510 | AB13: ='Model inputs'!AB8*('Model inputs'!B18*'Model inputs'!B6+'Model inputs'!B9) -> 510 | AC13: ='Model inputs'!AC8*('Model inputs'!B18*'Model inputs'!B6+'Model inputs'!B9) -> 510 | AD13: ='Model inputs'!AD8*('Model inputs'!B18*'Model inputs'!B6+'Model inputs'!B9) -> 510 | AE13: ='Model inputs'!AE8*('Model inputs'!B18*'Model inputs'!B6+'Model inputs'!B9) -> 510 | AF13: ='Model inputs'!AF8*('Model inputs'!B18*'Model inputs'!B6+'Model inputs'!B9) -> 510 | AG13: ='Model inputs'!AG8*('Model inputs'!B18*'Model inputs'!B6+'Model inputs'!B9) -> 510 | AH13: ='Model inputs'!AH8*('Model inputs'!B18*'Model inputs'!B6+'Model inputs'!B9) -> 510 | AI13: ='Model inputs'!AI8*('Model inputs'!B18*'Model inputs'!B6+'Model inputs'!B9) -> 510 | AJ13: ='Model inputs'!AJ8*('Model inputs'!B18*'Model inputs'!B6+'Model inputs'!B9) -> 510 | AK13: ='Model inputs'!AK8*('Model inputs'!B18*'Model inputs'!B6+'Model inputs'!B9) -> 510 | AL13: ='Model inputs'!AL8*('Model inputs'!B18*'Model inputs'!B6+'Model inputs'!B9) -> 510 | AM13: ='Model inputs'!AM8*('Model inputs'!B18*'Model inputs'!B6+'Model inputs'!B9) -> 510
A14: TenantGuard ending cash | C14: 0 | D14: =IF(IF(DATE(2026,10,1)=DATE(2026,10,1),IF('Model inputs'!B12="","",'Model inputs'!B12),IF('Model inputs'!C14="","",'Model inputs'!C14))="",0,IF(DATE(2026,10,1)=DATE(2026,10,1),IF('Model inputs'!B12="","",'Model inputs'!B12),IF('Model inputs'!C14="","",'Model inputs'!C14)))+'Model inputs'!D16 -> 856457.5 | E14: =IF(IF(DATE(2026,11,1)=DATE(2026,10,1),IF('Model inputs'!B12="","",'Model inputs'!B12),IF('Model inputs'!D14="","",'Model inputs'!D14))="",0,IF(DATE(2026,11,1)=DATE(2026,10,1),IF('Model inputs'!B12="","",'Model inputs'!B12),IF('Model inputs'!D14="","",'Model inputs'!D14)))+'Model inputs'!E16 -> 819372.5 | F14: =IF(IF(DATE(2026,12,1)=DATE(2026,10,1),IF('Model inputs'!B12="","",'Model inputs'!B12),IF('Model inputs'!E14="","",'Model inputs'!E14))="",0,IF(DATE(2026,12,1)=DATE(2026,10,1),IF('Model inputs'!B12="","",'Model inputs'!B12),IF('Model inputs'!E14="","",'Model inputs'!E14)))+'Model inputs'!F16 -> 788745 | G14: =IF(IF(DATE(2027,1,1)=DATE(2026,10,1),IF('Model inputs'!B12="","",'Model inputs'!B12),IF('Model inputs'!F14="","",'Model inputs'!F14))="",0,IF(DATE(2027,1,1)=DATE(2026,10,1),IF('Model inputs'!B12="","",'Model inputs'!B12),IF('Model inputs'!F14="","",'Model inputs'!F14)))+'Model inputs'!G16 -> 764575 | H14: =IF(IF(DATE(2027,2,1)=DATE(2026,10,1),IF('Model inputs'!B12="","",'Model inputs'!B12),IF('Model inputs'!G14="","",'Model inputs'!G14))="",0,IF(DATE(2027,2,1)=DATE(2026,10,1),IF('Model inputs'!B12="","",'Model inputs'!B12),IF('Model inputs'!G14="","",'Model inputs'!G14)))+'Model inputs'!H16 -> 746862.5 | I14: =IF(IF(DATE(2027,3,1)=DATE(2026,10,1),IF('Model inputs'!B12="","",'Model inputs'!B12),IF('Model inputs'!H14="","",'Model inputs'!H14))="",0,IF(DATE(2027,3,1)=DATE(2026,10,1),IF('Model inputs'!B12="","",'Model inputs'!B12),IF('Model inputs'!H14="","",'Model inputs'!H14)))+'Model inputs'!I16 -> 735607.5 | J14: =IF(IF(DATE(2027,4,1)=DATE(2026,10,1),IF('Model inputs'!B12="","",'Model inputs'!B12),IF('Model inputs'!I14="","",'Model inputs'!I14))="",0,IF(DATE(2027,4,1)=DATE(2026,10,1),IF('Model inputs'!B12="","",'Model inputs'!B12),IF('Model inputs'!I14="","",'Model inputs'!I14)))+'Model inputs'!J16 -> 730810 | K14: =IF(IF(DATE(2027,5,1)=DATE(2026,10,1),IF('Model inputs'!B12="","",'Model inputs'!B12),IF('Model inputs'!J14="","",'Model inputs'!J14))="",0,IF(DATE(2027,5,1)=DATE(2026,10,1),IF('Model inputs'!B12="","",'Model inputs'!B12),IF('Model inputs'!J14="","",'Model inputs'!J14)))+'Model inputs'!K16 -> 732470 | L14: =IF(IF(DATE(2027,6,1)=DATE(2026,10,1),IF('Model inputs'!B12="","",'Model inputs'!B12),IF('Model inputs'!K14="","",'Model inputs'!K14))="",0,IF(DATE(2027,6,1)=DATE(2026,10,1),IF('Model inputs'!B12="","",'Model inputs'!B12),IF('Model inputs'!K14="","",'Model inputs'!K14)))+'Model inputs'!L16 -> 740587.5 | M14: =IF(IF(DATE(2027,7,1)=DATE(2026,10,1),IF('Model inputs'!B12="","",'Model inputs'!B12),IF('Model inputs'!L14="","",'Model inputs'!L14))="",0,IF(DATE(2027,7,1)=DATE(2026,10,1),IF('Model inputs'!B12="","",'Model inputs'!B12),IF('Model inputs'!L14="","",'Model inputs'!L14)))+'Model inputs'!M16 -> 755162.5 | N14: =IF(IF(DATE(2027,8,1)=DATE(2026,10,1),IF('Model inputs'!B12="","",'Model inputs'!B12),IF('Model inputs'!M14="","",'Model inputs'!M14))="",0,IF(DATE(2027,8,1)=DATE(2026,10,1),IF('Model inputs'!B12="","",'Model inputs'!B12),IF('Model inputs'!M14="","",'Model inputs'!M14)))+'Model inputs'!N16 -> 776195 | O14: =IF(IF(DATE(2027,9,1)=DATE(2026,10,1),IF('Model inputs'!B12="","",'Model inputs'!B12),IF('Model inputs'!N14="","",'Model inputs'!N14))="",0,IF(DATE(2027,9,1)=DATE(2026,10,1),IF('Model inputs'!B12="","",'Model inputs'!B12),IF('Model inputs'!N14="","",'Model inputs'!N14)))+'Model inputs'!O16 -> 803685 | P14: =IF(IF(DATE(2027,10,1)=DATE(2026,10,1),IF('Model inputs'!B12="","",'Model inputs'!B12),IF('Model inputs'!O14="","",'Model inputs'!O14))="",0,IF(DATE(2027,10,1)=DATE(2026,10,1),IF('Model inputs'!B12="","",'Model inputs'!B12),IF('Model inputs'!O14="","",'Model inputs'!O14)))+'Model inputs'!P16 -> 831175 | Q14: =IF(IF(DATE(2027,11,1)=DATE(2026,10,1),IF('Model inputs'!B12="","",'Model inputs'!B12),IF('Model inputs'!P14="","",'Model inputs'!P14))="",0,IF(DATE(2027,11,1)=DATE(2026,10,1),IF('Model inputs'!B12="","",'Model inputs'!B12),IF('Model inputs'!P14="","",'Model inputs'!P14)))+'Model inputs'!Q16 -> 858665 | R14: =IF(IF(DATE(2027,12,1)=DATE(2026,10,1),IF('Model inputs'!B12="","",'Model inputs'!B12),IF('Model inputs'!Q14="","",'Model inputs'!Q14))="",0,IF(DATE(2027,12,1)=DATE(2026,10,1),IF('Model inputs'!B12="","",'Model inputs'!B12),IF('Model inputs'!Q14="","",'Model inputs'!Q14)))+'Model inputs'!R16 -> 886155 | S14: =IF(IF(DATE(2028,1,1)=DATE(2026,10,1),IF('Model inputs'!B12="","",'Model inputs'!B12),IF('Model inputs'!R14="","",'Model inputs'!R14))="",0,IF(DATE(2028,1,1)=DATE(2026,10,1),IF('Model inputs'!B12="","",'Model inputs'!B12),IF('Model inputs'!R14="","",'Model inputs'!R14)))+'Model inputs'!S16 -> 913645 | T14: =IF(IF(DATE(2028,2,1)=DATE(2026,10,1),IF('Model inputs'!B12="","",'Model inputs'!B12),IF('Model inputs'!S14="","",'Model inputs'!S14))="",0,IF(DATE(2028,2,1)=DATE(2026,10,1),IF('Model inputs'!B12="","",'Model inputs'!B12),IF('Model inputs'!S14="","",'Model inputs'!S14)))+'Model inputs'!T16 -> 941135 | U14: =IF(IF(DATE(2028,3,1)=DATE(2026,10,1),IF('Model inputs'!B12="","",'Model inputs'!B12),IF('Model inputs'!T14="","",'Model inputs'!T14))="",0,IF(DATE(2028,3,1)=DATE(2026,10,1),IF('Model inputs'!B12="","",'Model inputs'!B12),IF('Model inputs'!T14="","",'Model inputs'!T14)))+'Model inputs'!U16 -> 968625 | V14: =IF(IF(DATE(2028,4,1)=DATE(2026,10,1),IF('Model inputs'!B12="","",'Model inputs'!B12),IF('Model inputs'!U14="","",'Model inputs'!U14))="",0,IF(DATE(2028,4,1)=DATE(2026,10,1),IF('Model inputs'!B12="","",'Model inputs'!B12),IF('Model inputs'!U14="","",'Model inputs'!U14)))+'Model inputs'!V16 -> 996115 | W14: =IF(IF(DATE(2028,5,1)=DATE(2026,10,1),IF('Model inputs'!B12="","",'Model inputs'!B12),IF('Model inputs'!V14="","",'Model inputs'!V14))="",0,IF(DATE(2028,5,1)=DATE(2026,10,1),IF('Model inputs'!B12="","",'Model inputs'!B12),IF('Model inputs'!V14="","",'Model inputs'!V14)))+'Model inputs'!W16 -> 1023605 | X14: =IF(IF(DATE(2028,6,1)=DATE(2026,10,1),IF('Model inputs'!B12="","",'Model inputs'!B12),IF('Model inputs'!W14="","",'Model inputs'!W14))="",0,IF(DATE(2028,6,1)=DATE(2026,10,1),IF('Model inputs'!B12="","",'Model inputs'!B12),IF('Model inputs'!W14="","",'Model inputs'!W14)))+'Model inputs'!X16 -> 1051095 | Y14: =IF(IF(DATE(2028,7,1)=DATE(2026,10,1),IF('Model inputs'!B12="","",'Model inputs'!B12),IF('Model inputs'!X14="","",'Model inputs'!X14))="",0,IF(DATE(2028,7,1)=DATE(2026,10,1),IF('Model inputs'!B12="","",'Model inputs'!B12),IF('Model inputs'!X14="","",'Model inputs'!X14)))+'Model inputs'!Y16 -> 1078585 | Z14: =IF(IF(DATE(2028,8,1)=DATE(2026,10,1),IF('Model inputs'!B12="","",'Model inputs'!B12),IF('Model inputs'!Y14="","",'Model inputs'!Y14))="",0,IF(DATE(2028,8,1)=DATE(2026,10,1),IF('Model inputs'!B12="","",'Model inputs'!B12),IF('Model inputs'!Y14="","",'Model inputs'!Y14)))+'Model inputs'!Z16 -> 1106075 | AA14: =IF(IF(DATE(2028,9,1)=DATE(2026,10,1),IF('Model inputs'!B12="","",'Model inputs'!B12),IF('Model inputs'!Z14="","",'Model inputs'!Z14))="",0,IF(DATE(2028,9,1)=DATE(2026,10,1),IF('Model inputs'!B12="","",'Model inputs'!B12),IF('Model inputs'!Z14="","",'Model inputs'!Z14)))+'Model inputs'!AA16 -> 1133565 | AB14: =IF(IF(DATE(2028,10,1)=DATE(2026,10,1),IF('Model inputs'!B12="","",'Model inputs'!B12),IF('Model inputs'!AA14="","",'Model inputs'!AA14))="",0,IF(DATE(2028,10,1)=DATE(2026,10,1),IF('Model inputs'!B12="","",'Model inputs'!B12),IF('Model inputs'!AA14="","",'Model inputs'!AA14)))+'Model inputs'!AB16 -> 1161055 | AC14: =IF(IF(DATE(2028,11,1)=DATE(2026,10,1),IF('Model inputs'!B12="","",'Model inputs'!B12),IF('Model inputs'!AB14="","",'Model inputs'!AB14))="",0,IF(DATE(2028,11,1)=DATE(2026,10,1),IF('Model inputs'!B12="","",'Model inputs'!B12),IF('Model inputs'!AB14="","",'Model inputs'!AB14)))+'Model inputs'!AC16 -> 1188545 | AD14: =IF(IF(DATE(2028,12,1)=DATE(2026,10,1),IF('Model inputs'!B12="","",'Model inputs'!B12),IF('Model inputs'!AC14="","",'Model inputs'!AC14))="",0,IF(DATE(2028,12,1)=DATE(2026,10,1),IF('Model inputs'!B12="","",'Model inputs'!B12),IF('Model inputs'!AC14="","",'Model inputs'!AC14)))+'Model inputs'!AD16 -> 1216035 | AE14: =IF(IF(DATE(2029,1,1)=DATE(2026,10,1),IF('Model inputs'!B12="","",'Model inputs'!B12),IF('Model inputs'!AD14="","",'Model inputs'!AD14))="",0,IF(DATE(2029,1,1)=DATE(2026,10,1),IF('Model inputs'!B12="","",'Model inputs'!B12),IF('Model inputs'!AD14="","",'Model inputs'!AD14)))+'Model inputs'!AE16 -> 1243525 | AF14: =IF(IF(DATE(2029,2,1)=DATE(2026,10,1),IF('Model inputs'!B12="","",'Model inputs'!B12),IF('Model inputs'!AE14="","",'Model inputs'!AE14))="",0,IF(DATE(2029,2,1)=DATE(2026,10,1),IF('Model inputs'!B12="","",'Model inputs'!B12),IF('Model inputs'!AE14="","",'Model inputs'!AE14)))+'Model inputs'!AF16 -> 1271015 | AG14: =IF(IF(DATE(2029,3,1)=DATE(2026,10,1),IF('Model inputs'!B12="","",'Model inputs'!B12),IF('Model inputs'!AF14="","",'Model inputs'!AF14))="",0,IF(DATE(2029,3,1)=DATE(2026,10,1),IF('Model inputs'!B12="","",'Model inputs'!B12),IF('Model inputs'!AF14="","",'Model inputs'!AF14)))+'Model inputs'!AG16 -> 1298505 | AH14: =IF(IF(DATE(2029,4,1)=DATE(2026,10,1),IF('Model inputs'!B12="","",'Model inputs'!B12),IF('Model inputs'!AG14="","",'Model inputs'!AG14))="",0,IF(DATE(2029,4,1)=DATE(2026,10,1),IF('Model inputs'!B12="","",'Model inputs'!B12),IF('Model inputs'!AG14="","",'Model inputs'!AG14)))+'Model inputs'!AH16 -> 1325995 | AI14: =IF(IF(DATE(2029,5,1)=DATE(2026,10,1),IF('Model inputs'!B12="","",'Model inputs'!B12),IF('Model inputs'!AH14="","",'Model inputs'!AH14))="",0,IF(DATE(2029,5,1)=DATE(2026,10,1),IF('Model inputs'!B12="","",'Model inputs'!B12),IF('Model inputs'!AH14="","",'Model inputs'!AH14)))+'Model inputs'!AI16 -> 1353485 | AJ14: =IF(IF(DATE(2029,6,1)=DATE(2026,10,1),IF('Model inputs'!B12="","",'Model inputs'!B12),IF('Model inputs'!AI14="","",'Model inputs'!AI14))="",0,IF(DATE(2029,6,1)=DATE(2026,10,1),IF('Model inputs'!B12="","",'Model inputs'!B12),IF('Model inputs'!AI14="","",'Model inputs'!AI14)))+'Model inputs'!AJ16 -> 1380975 | AK14: =IF(IF(DATE(2029,7,1)=DATE(2026,10,1),IF('Model inputs'!B12="","",'Model inputs'!B12),IF('Model inputs'!AJ14="","",'Model inputs'!AJ14))="",0,IF(DATE(2029,7,1)=DATE(2026,10,1),IF('Model inputs'!B12="","",'Model inputs'!B12),IF('Model inputs'!AJ14="","",'Model inputs'!AJ14)))+'Model inputs'!AK16 -> 1408465 | AL14: =IF(IF(DATE(2029,8,1)=DATE(2026,10,1),IF('Model inputs'!B12="","",'Model inputs'!B12),IF('Model inputs'!AK14="","",'Model inputs'!AK14))="",0,IF(DATE(2029,8,1)=DATE(2026,10,1),IF('Model inputs'!B12="","",'Model inputs'!B12),IF('Model inputs'!AK14="","",'Model inputs'!AK14)))+'Model inputs'!AL16 -> 1435955 | AM14: =IF(IF(DATE(2029,9,1)=DATE(2026,10,1),IF('Model inputs'!B12="","",'Model inputs'!B12),IF('Model inputs'!AL14="","",'Model inputs'!AL14))="",0,IF(DATE(2029,9,1)=DATE(2026,10,1),IF('Model inputs'!B12="","",'Model inputs'!B12),IF('Model inputs'!AL14="","",'Model inputs'!AL14)))+'Model inputs'!AM16 -> 1463445
A15: TenantGuard fixed operating spend | C15: 0 | D15: =IF('Model inputs'!B11="","",'Model inputs'!B11) -> 50000 | E15: =IF('Model inputs'!B11="","",'Model inputs'!B11) -> 50000 | F15: =IF('Model inputs'!B11="","",'Model inputs'!B11) -> 50000 | G15: =IF('Model inputs'!B11="","",'Model inputs'!B11) -> 50000 | H15: =IF('Model inputs'!B11="","",'Model inputs'!B11) -> 50000 | I15: =IF('Model inputs'!B11="","",'Model inputs'!B11) -> 50000 | J15: =IF('Model inputs'!B11="","",'Model inputs'!B11) -> 50000 | K15: =IF('Model inputs'!B11="","",'Model inputs'!B11) -> 50000 | L15: =IF('Model inputs'!B11="","",'Model inputs'!B11) -> 50000 | M15: =IF('Model inputs'!B11="","",'Model inputs'!B11) -> 50000 | N15: =IF('Model inputs'!B11="","",'Model inputs'!B11) -> 50000 | O15: =IF('Model inputs'!B11="","",'Model inputs'!B11) -> 50000 | P15: =IF('Model inputs'!B11="","",'Model inputs'!B11) -> 50000 | Q15: =IF('Model inputs'!B11="","",'Model inputs'!B11) -> 50000 | R15: =IF('Model inputs'!B11="","",'Model inputs'!B11) -> 50000 | S15: =IF('Model inputs'!B11="","",'Model inputs'!B11) -> 50000 | T15: =IF('Model inputs'!B11="","",'Model inputs'!B11) -> 50000 | U15: =IF('Model inputs'!B11="","",'Model inputs'!B11) -> 50000 | V15: =IF('Model inputs'!B11="","",'Model inputs'!B11) -> 50000 | W15: =IF('Model inputs'!B11="","",'Model inputs'!B11) -> 50000 | X15: =IF('Model inputs'!B11="","",'Model inputs'!B11) -> 50000 | Y15: =IF('Model inputs'!B11="","",'Model inputs'!B11) -> 50000 | Z15: =IF('Model inputs'!B11="","",'Model inputs'!B11) -> 50000 | AA15: =IF('Model inputs'!B11="","",'Model inputs'!B11) -> 50000 | AB15: =IF('Model inputs'!B11="","",'Model inputs'!B11) -> 50000 | AC15: =IF('Model inputs'!B11="","",'Model inputs'!B11) -> 50000 | AD15: =IF('Model inputs'!B11="","",'Model inputs'!B11) -> 50000 | AE15: =IF('Model inputs'!B11="","",'Model inputs'!B11) -> 50000 | AF15: =IF('Model inputs'!B11="","",'Model inputs'!B11) -> 50000 | AG15: =IF('Model inputs'!B11="","",'Model inputs'!B11) -> 50000 | AH15: =IF('Model inputs'!B11="","",'Model inputs'!B11) -> 50000 | AI15: =IF('Model inputs'!B11="","",'Model inputs'!B11) -> 50000 | AJ15: =IF('Model inputs'!B11="","",'Model inputs'!B11) -> 50000 | AK15: =IF('Model inputs'!B11="","",'Model inputs'!B11) -> 50000 | AL15: =IF('Model inputs'!B11="","",'Model inputs'!B11) -> 50000 | AM15: =IF('Model inputs'!B11="","",'Model inputs'!B11) -> 50000
A16: TenantGuard net cash flow | C16: 0 | D16: ='Model inputs'!D17-'Model inputs'!D13-'Model inputs'!D15 -> -43542.5 | E16: ='Model inputs'!E17-'Model inputs'!E13-'Model inputs'!E15 -> -37085 | F16: ='Model inputs'!F17-'Model inputs'!F13-'Model inputs'!F15 -> -30627.5 | G16: ='Model inputs'!G17-'Model inputs'!G13-'Model inputs'!G15 -> -24170 | H16: ='Model inputs'!H17-'Model inputs'!H13-'Model inputs'!H15 -> -17712.5 | I16: ='Model inputs'!I17-'Model inputs'!I13-'Model inputs'!I15 -> -11255 | J16: ='Model inputs'!J17-'Model inputs'!J13-'Model inputs'!J15 -> -4797.5 | K16: ='Model inputs'!K17-'Model inputs'!K13-'Model inputs'!K15 -> 1660 | ... AM16: ='Model inputs'!AM17-'Model inputs'!AM13-'Model inputs'!AM15 -> 27490
A17: TenantGuard revenue | C17: 0 | D17: ='Model inputs'!D10*'Model inputs'!B7 -> 6500 | E17: ='Model inputs'!E10*'Model inputs'!B7 -> 13000 | F17: ='Model inputs'!F10*'Model inputs'!B7 -> 19500 | G17: ='Model inputs'!G10*'Model inputs'!B7 -> 26000 | H17: ='Model inputs'!H10*'Model inputs'!B7 -> 32500 | I17: ='Model inputs'!I10*'Model inputs'!B7 -> 39000 | J17: ='Model inputs'!J10*'Model inputs'!B7 -> 45500 | K17: ='Model inputs'!K10*'Model inputs'!B7 -> 52000 | L17: ='Model inputs'!L10*'Model inputs'!B7 -> 58500 | M17: ='Model inputs'!M10*'Model inputs'!B7 -> 65000 | N17: ='Model inputs'!N10*'Model inputs'!B7 -> 71500 | O17: ='Model inputs'!O10*'Model inputs'!B7 -> 78000 | P17: ='Model inputs'!P10*'Model inputs'!B7 -> 78000 | Q17: ='Model inputs'!Q10*'Model inputs'!B7 -> 78000 | R17: ='Model inputs'!R10*'Model inputs'!B7 -> 78000 | S17: ='Model inputs'!S10*'Model inputs'!B7 -> 78000 | T17: ='Model inputs'!T10*'Model inputs'!B7 -> 78000 | U17: ='Model inputs'!U10*'Model inputs'!B7 -> 78000 | V17: ='Model inputs'!V10*'Model inputs'!B7 -> 78000 | W17: ='Model inputs'!W10*'Model inputs'!B7 -> 78000 | X17: ='Model inputs'!X10*'Model inputs'!B7 -> 78000 | Y17: ='Model inputs'!Y10*'Model inputs'!B7 -> 78000 | Z17: ='Model inputs'!Z10*'Model inputs'!B7 -> 78000 | AA17: ='Model inputs'!AA10*'Model inputs'!B7 -> 78000 | AB17: ='Model inputs'!AB10*'Model inputs'!B7 -> 78000 | AC17: ='Model inputs'!AC10*'Model inputs'!B7 -> 78000 | AD17: ='Model inputs'!AD10*'Model inputs'!B7 -> 78000 | AE17: ='Model inputs'!AE10*'Model inputs'!B7 -> 78000 | AF17: ='Model inputs'!AF10*'Model inputs'!B7 -> 78000 | AG17: ='Model inputs'!AG10*'Model inputs'!B7 -> 78000 | AH17: ='Model inputs'!AH10*'Model inputs'!B7 -> 78000 | AI17: ='Model inputs'!AI10*'Model inputs'!B7 -> 78000 | AJ17: ='Model inputs'!AJ10*'Model inputs'!B7 -> 78000 | AK17: ='Model inputs'!AK10*'Model inputs'!B7 -> 78000 | AL17: ='Model inputs'!AL10*'Model inputs'!B7 -> 78000 | AM17: ='Model inputs'!AM10*'Model inputs'!B7 -> 78000
A18: Token cost per attempt | B18: =0.005 -> 0.005
A19: Customer losses | C19: 0 | D19: ='Model inputs'!D22*'Model inputs'!B28 -> 0 | E19: ='Model inputs'!E22*'Model inputs'!B28 -> 0.1 | F19: ='Model inputs'!F22*'Model inputs'!B28 -> 0.2 | G19: ='Model inputs'!G22*'Model inputs'!B28 -> 0.3 | H19: ='Model inputs'!H22*'Model inputs'!B28 -> 0.4 | I19: ='Model inputs'!I22*'Model inputs'!B28 -> 0.5 | J19: ='Model inputs'!J22*'Model inputs'!B28 -> 0.6 | K19: ='Model inputs'!K22*'Model inputs'!B28 -> 0.7 | L19: ='Model inputs'!L22*'Model inputs'!B28 -> 0.8 | M19: ='Model inputs'!M22*'Model inputs'!B28 -> 0.9 | N19: ='Model inputs'!N22*'Model inputs'!B28 -> 1 | O19: ='Model inputs'!O22*'Model inputs'!B28 -> 1.1 | P19: ='Model inputs'!P22*'Model inputs'!B28 -> 1.2 | Q19: ='Model inputs'!Q22*'Model inputs'!B28 -> 1.2 | R19: ='Model inputs'!R22*'Model inputs'!B28 -> 1.2 | S19: ='Model inputs'!S22*'Model inputs'!B28 -> 1.2 | T19: ='Model inputs'!T22*'Model inputs'!B28 -> 1.2 | U19: ='Model inputs'!U22*'Model inputs'!B28 -> 1.2 | V19: ='Model inputs'!V22*'Model inputs'!B28 -> 1.2 | W19: ='Model inputs'!W22*'Model inputs'!B28 -> 1.2 | X19: ='Model inputs'!X22*'Model inputs'!B28 -> 1.2 | Y19: ='Model inputs'!Y22*'Model inputs'!B28 -> 1.2 | Z19: ='Model inputs'!Z22*'Model inputs'!B28 -> 1.2 | AA19: ='Model inputs'!AA22*'Model inputs'!B28 -> 1.2 | AB19: ='Model inputs'!AB22*'Model inputs'!B28 -> 1.2 | AC19: ='Model inputs'!AC22*'Model inputs'!B28 -> 1.2 | AD19: ='Model inputs'!AD22*'Model inputs'!B28 -> 1.2 | AE19: ='Model inputs'!AE22*'Model inputs'!B28 -> 1.2 | AF19: ='Model inputs'!AF22*'Model inputs'!B28 -> 1.2 | AG19: ='Model inputs'!AG22*'Model inputs'!B28 -> 1.2 | AH19: ='Model inputs'!AH22*'Model inputs'!B28 -> 1.2 | AI19: ='Model inputs'!AI22*'Model inputs'!B28 -> 1.2 | AJ19: ='Model inputs'!AJ22*'Model inputs'!B28 -> 1.2 | AK19: ='Model inputs'!AK22*'Model inputs'!B28 -> 1.2 | AL19: ='Model inputs'!AL22*'Model inputs'!B28 -> 1.2 | AM19: ='Model inputs'!AM22*'Model inputs'!B28 -> 1.2
A20: Fixes per customer per month · Completed remediations | B20: =100 -> 100
